Workbook

Sheet NOC&MCD
A1: NOC and MCD
A2: Money to Invest | B2: 100000000
A3: Risk Free Rate | B3: ='10-year_Bond'!B14 -> 0.0423
A4: Proportion of NOC | B4: 0.5
A5: Proportion of of MCD | B5: =1-B4 -> 0.5
I7: Asset Montley Returns | J7: NOC | K7: MCD | L7: Portfolio | O7: Asset Yearly Returns | P7: NOC | Q7: MCD | R7: Portfolio | T7: Final Look of the Portfolio
A8: Date | B8: NOC Price | C8: MCD Price | E8: NOC Return | F8: MCD Return | G8: 2 Stock Portfolio Return | I8: Mean Return | J8: =AVERAGE(E9:E127) -> 0.012007055 | K8: =AVERAGE(F9:F127) -> 0.011117206 | L8: =AVERAGE(G9:G127) -> 0.011562131 | O8: Mean Return | P8: =(1+J8)^12-1 -> 0.15399116 | Q8: =(1+K8)^12-1 -> 0.14187354 | R8: =(1+L8)^12-1 -> 0.14791769 | T8: Stock | U8: NOC | V8: MCD | W8: Bonds
A9: 45747 | B9: 512.01 | C9: 312.37 | E9: =B9/B10-1 -> 0.10887079 | F9: =C9/C10-1 -> 0.013102844 | G9: =E9*$B$4+F9*$B$5 -> 0.060986819 | I9: Variance | J9: =_xlfn.VAR.P(E9:E127) -> 0.003732766 | K9: =_xlfn.VAR.P(F9:F127) -> 0.0024389541 | L9: =_xlfn.VAR.P(G9:G127) -> 0.0021330982 | O9: Variance | P9: =(1+J9)^12-1 -> 0.045724344 | Q9: =(1+K9)^12-1 -> 0.029663259 | R9: =(1+L9)^12-1 -> 0.025899631 | T9: Weight | U9: =T34*M45 -> 0.36 | V9: =1-U9-W9 -> 0.54 | W9: =1-T34 -> 0.1
A10: 45716 | B10: 461.74 | C10: 308.33 | E10: =B10/B11-1 -> -0.05239395 | F10: =C10/C11-1 -> 0.067994458 | G10: =E10*$B$4+F10*$B$5 -> 0.007800254 | I10: Standard deviation | J10: =_xlfn.STDEV.P(E9:E127) -> 0.061096366 | K10: =_xlfn.STDEV.P(F9:F127) -> 0.049385768 | L10: =_xlfn.STDEV.P(G9:G127) -> 0.046185476 | O10: Standard deviation | P10: =J10*SQRT(12) -> 0.21164402 | Q10: =K10*SQRT(12) -> 0.17107732 | R10: =L10*SQRT(12) -> 0.15999118 | T10: Capital Allocation | U10: =U9*$B$2 -> 36000000 | V10: =V9*$B$2 -> 54000000 | W10: =W9*$B$2 -> 10000000
A11: 45688 | B11: 487.27 | C11: 288.7 | E11: =B11/B12-1 -> 0.038313197 | F11: =C11/C12-1 -> -0.0041050053 | G11: =E11*$B$4+F11*$B$5 -> 0.017104096 | I11: Covariance | K11: =_xlfn.COVARIANCE.P(E9:E127,F9:F127) -> 0.0011803363 | T11: Annual Return % | U11: =P8 -> 0.15399116 | V11: =Q8 -> 0.14187354 | W11: =B3 -> 0.0423
A12: 45657 | B12: 469.29 | C12: 289.89 | E12: =B12/B13-1 -> -0.041580721 | F12: =C12/C13-1 -> -0.020674977 | G12: =E12*$B$4+F12*$B$5 -> -0.031127849 | T12: Annual Return $ | U12: =U10*U11 -> 5543681.7 | V12: =V10*V11 -> 7661171.1 | W12: =W10*W11 -> 423000
A13: 45625 | B13: 489.65 | C13: 296.01 | E13: =B13/B14-1 -> -0.038053515 | F13: =C13/C14-1 -> 0.013351135 | G13: =E13*$B$4+F13*$B$5 -> -0.01235119 | I13: Portfolio mean return | T13: Portfolio Return | U13: =SUM(U12:W12)/B2 -> 0.13627853
A14: 45596 | B14: 509.02 | C14: 292.11 | E14: =B14/B15-1 -> -0.036074763 | F14: =C14/C15-1 -> -0.040721159 | G14: =E14*$B$4+F14*$B$5 -> -0.038397961 | I14: Monthly | J14: =AVERAGE(G9:G127) -> 0.011562131 | T14: Portfolio Beta | U14: =U9*'SPY&BETA'!L5+V9*'SPY&BETA'!M5 -> 0.48828574
A15: 45565 | B15: 528.07 | C15: 304.51 | E15: =B15/B16-1 -> 0.0092888133 | F15: =C15/C16-1 -> 0.054908889 | G15: =E15*$B$4+F15*$B$5 -> 0.032098851 | I15: Monthly | J15: =J8*B4+K8*B5 -> 0.011562131 | T15: Treynor ratio | U15: =(U13-B3)/U14 -> 0.19246625
A16: 45534 | B16: 523.21 | C16: 288.66 | E16: =B16/B17-1 -> 0.08029815 | F16: =C16/C17-1 -> 0.087641296 | G16: =E16*$B$4+F16*$B$5 -> 0.083969723 | I16: Annual | J16: =(1+J15)^12-1 -> 0.14791769 | T16: VaR (90%) | U16: =1.28*(L10/SQRT(12))*B2 -> 1706572.6
A17: 45504 | B17: 484.32 | C17: 265.4 | E17: =B17/B18-1 -> 0.11095309 | F17: =C17/C18-1 -> 0.041437765 | G17: =E17*$B$4+F17*$B$5 -> 0.076195428 | I17: Market Excess Return | J17: =J16-B3 -> 0.10561769
A18: 45471 | B18: 435.95 | C18: 254.84 | E18: =B18/B19-1 -> -0.032877077 | F18: =C18/C19-1 -> -0.01564371 | G18: =E18*$B$4+F18*$B$5 -> -0.024260393 | I18: Portfolio return variance | J18: =_xlfn.VAR.P(G9:G127) -> 0.0021330982
A19: 45443 | B19: 450.77 | C19: 258.89 | E19: =B19/B20-1 -> -0.070634806 | F19: =C19/C20-1 -> -0.051823909 | G19: =E19*$B$4+F19*$B$5 -> -0.061229357
A20: 45412 | B20: 485.03 | C20: 273.04 | E20: =B20/B21-1 -> 0.013307985 | F20: =C20/C21-1 -> -0.031601348 | G20: =E20*$B$4+F20*$B$5 -> -0.0091466815 | I20: Portfolio return STD | J20: =SQRT(J18) -> 0.046185476
A21: 45379 | B21: 478.66 | C21: 281.95 | E21: =B21/B22-1 -> 0.038262982 | F21: =C21/C22-1 -> -0.035342822 | G21: =E21*$B$4+F21*$B$5 -> 0.0014600801 | I21: Annual | J21: =SQRT(12)*J20 -> 0.15999118 | M21: Yearly Porfolio Statistics
A22: 45351 | B22: 461.02 | C22: 292.28 | E22: =B22/B23-1 -> 0.031918704 | F22: =C22/C23-1 -> -0.0015031429 | G22: =E22*$B$4+F22*$B$5 -> 0.01520778 | M22: % of NOC | N22: Std dev P | O22: Exp Ret P | P22: Sharp Ratio
A23: 45322 | B23: 446.76 | C23: 292.72 | E23: =B23/B24-1 -> -0.045670099 | F23: =C23/C24-1 -> -0.012782031 | G23: =E23*$B$4+F23*$B$5 -> -0.029226065 | N23: =J21 -> 0.15999118 | O23: =J16 -> 0.14791769 | P23: =(O23-$B$3)/N23 -> 0.66014696 | T23: Capital Allocation Line
A24: 45289 | B24: 468.14 | C24: 296.51 | E24: =B24/B25-1 -> -0.014773971 | F24: =C24/C25-1 -> 0.052050809 | G24: =E24*$B$4+F24*$B$5 -> 0.018638419 | M24: 0 | N24: 0.17107732 | O24: 0.14187354 | P24: =(O24-$B$3)/N24 -> 0.58203823 | T24: Weight | U24: Return | V24: St Dev
A25: 45260 | B25: 475.16 | C25: 281.84 | E25: =B25/B26-1 -> 0.0079120972 | F25: =C25/C26-1 -> 0.075027654 | G25: =E25*$B$4+F25*$B$5 -> 0.041469876 | M25: 0.05 | N25: 0.16694741 | O25: 0.14247664 | P25: =(O25-$B$3)/N25 -> 0.60004906 | T25: 0 | U25: =(T25*$O$32)+((1-T25)*$B$3) -> 0.0423 | V25: =T25*$N$45 -> 0
A26: 45230 | B26: 471.43 | C26: 262.17 | E26: =B26/B27-1 -> 0.070969354 | F26: =C26/C27-1 -> -0.0048208321 | G26: =E26*$B$4+F26*$B$5 -> 0.033074261 | M26: 0.1 | N26: 0.16341387 | O26: 0.14308003 | P26: =(O26-$B$3)/N26 -> 0.61671652 | T26: 0.1 | U26: =(T26*$O$45)+((1-T26)*$B$3) -> 0.052740652 | V26: =T26*$N$45 -> 0.015653092
A27: 45198 | B27: 440.19 | C27: 263.44 | E27: =B27/B28-1 -> 0.016393821 | F27: =C27/C28-1 -> -0.062991286 | G27: =E27*$B$4+F27*$B$5 -> -0.023298732 | M27: 0.15 | N27: 0.16051607 | O27: 0.14368372 | P27: =(O27-$B$3)/N27 -> 0.63161101 | T27: 0.2 | U27: =(T27*$O$45)+((1-T27)*$B$3) -> 0.063181304 | V27: =T27*$N$45 -> 0.031306184
A28: 45169 | B28: 433.09 | C28: 281.15 | E28: =B28/B29-1 -> -0.026764045 | F28: =C28/C29-1 -> -0.041098226 | G28: =E28*$B$4+F28*$B$5 -> -0.033931136 | M28: 0.2 | N28: 0.15828893 | O28: 0.14428769 | P28: =(O28-$B$3)/N28 -> 0.64431347 | T28: 0.3 | U28: =(T28*$O$45)+((1-T28)*$B$3) -> 0.073621956 | V28: =T28*$N$45 -> 0.046959277
A29: 45138 | B29: 445 | C29: 293.2 | E29: =B29/B30-1 -> -0.023694603 | F29: =C29/C30-1 -> -0.0174592 | G29: =E29*$B$4+F29*$B$5 -> -0.020576902 | M29: 0.25 | N29: 0.15676105 | O29: 0.14489196 | P29: =(O29-$B$3)/N29 -> 0.65444801 | T29: 0.4 | U29: =(T29*$O$45)+((1-T29)*$B$3) -> 0.084062608 | V29: =T29*$N$45 -> 0.062612369
A30: 45107 | B30: 455.8 | C30: 298.41 | E30: =B30/B31-1 -> 0.046637121 | F30: =C30/C31-1 -> 0.046648662 | G30: =E30*$B$4+F30*$B$5 -> 0.046642892 | M30: 0.3 | N30: 0.15595298 | O30: 0.14549652 | P30: =(O30-$B$3)/N30 -> 0.6617156 | T30: 0.5 | U30: =(T30*$O$45)+((1-T30)*$B$3) -> 0.09450326 | V30: =T30*$N$45 -> 0.078265461
A31: 45077 | B31: 435.49 | C31: 285.11 | E31: =B31/B32-1 -> -0.055889176 | F31: =C31/C32-1 -> -0.035976331 | G31: =E31*$B$4+F31*$B$5 -> -0.045932753 | M31: 0.35 | N31: 0.15587591 | O31: 0.14610137 | P31: =(O31-$B$3)/N31 -> 0.66592313 | T31: 0.6 | U31: =(T31*$O$45)+((1-T31)*$B$3) -> 0.10494391 | V31: =T31*$N$45 -> 0.093918553
A32: 45044 | B32: 461.27 | C32: 295.75 | E32: =B32/B33-1 -> -0.00097461665 | F32: =C32/C33-1 -> 0.057723257 | G32: =E32*$B$4+F32*$B$5 -> 0.02837432 | M32: 0.4 | N32: 0.15653092 | O32: 0.14670652 | P32: =(O32-$B$3)/N32 -> 0.66700253 | T32: 0.7 | U32: =(T32*$O$45)+((1-T32)*$B$3) -> 0.11538456 | V32: =T32*$N$45 -> 0.10957165
A33: 45016 | B33: 461.72 | C33: 279.61 | E33: =B33/B34-1 -> -0.0051496412 | F33: =C33/C34-1 -> 0.059489978 | G33: =E33*$B$4+F33*$B$5 -> 0.027170168 | M33: 0.45 | N33: 0.15790891 | O33: 0.14731196 | P33: =(O33-$B$3)/N33 -> 0.66501607 | T33: 0.8 | U33: =(T33*$O$45)+((1-T33)*$B$3) -> 0.12582522 | V33: =T33*$N$45 -> 0.12522474
A34: 44985 | B34: 464.11 | C34: 263.91 | E34: =B34/B35-1 -> 0.035867333 | F34: =C34/C35-1 -> -0.013051608 | G34: =E34*$B$4+F34*$B$5 -> 0.011407863 | M34: 0.5 | N34: 0.15999118 | O34: 0.14791769 | P34: =(O34-$B$3)/N34 -> 0.66014696 | T34: 0.9 | U34: =(T34*$O$45)+((1-T34)*$B$3) -> 0.13626587 | V34: =T34*$N$45 -> 0.14087783
A35: 44957 | B35: 448.04 | C35: 267.4 | E35: =B35/B36-1 -> -0.17882737 | F35: =C35/C36-1 -> 0.014685235 | G35: =E35*$B$4+F35*$B$5 -> -0.082071066 | M35: 0.55 | N35: 0.16275072 | O35: 0.14852372 | P35: =(O35-$B$3)/N35 -> 0.65267741 | T35: 1 | U35: =(T35*$O$45)+((1-T35)*$B$3) -> 0.14670652 | V35: =T35*$N$45 -> 0.15653092
A36: 44925 | B36: 545.61 | C36: 263.53 | E36: =B36/B37-1 -> 0.023101877 | F36: =C36/C37-1 -> -0.033945526 | G36: =E36*$B$4+F36*$B$5 -> -0.0054218244 | M36: 0.6 | N36: 0.16615378 | O36: 0.14913004 | P36: =(O36-$B$3)/N36 -> 0.64295881 | T36: 2 | U36: =(T36*$O$45)+((1-T36)*$B$3) -> 0.25111304 | V36: =T36*$N$45 -> 0.31306184
A37: 44895 | B37: 533.29 | C37: 272.79 | E37: =B37/B38-1 -> -0.028633358 | F37: =C37/C38-1 -> 0.00047678427 | G37: =E37*$B$4+F37*$B$5 -> -0.014078287 | M37: 0.65 | N37: 0.17016175 | O37: 0.14973665 | P37: =(O37-$B$3)/N37 -> 0.63137953
A38: 44865 | B38: 549.01 | C38: 272.66 | E38: =B38/B39-1 -> 0.16731162 | F38: =C38/C39-1 -> 0.18167635 | G38: =E38*$B$4+F38*$B$5 -> 0.17449398 | M38: 0.7 | N38: 0.17473302 | O38: 0.15034355 | P38: =(O38-$B$3)/N38 -> 0.61833506
A39: 44834 | B39: 470.32 | C39: 230.74 | E39: =B39/B40-1 -> -0.016046361 | F39: =C39/C40-1 -> -0.085381322 | G39: =E39*$B$4+F39*$B$5 -> -0.050713842 | M39: 0.75 | N39: 0.17982463 | O39: 0.15095075 | P39: =(O39-$B$3)/N39 -> 0.60420394
A40: 44804 | B40: 477.99 | C40: 252.28 | E40: =B40/B41-1 -> -0.0019001879 | F40: =C40/C41-1 -> -0.042108061 | G40: =E40*$B$4+F40*$B$5 -> -0.022004124 | M40: 0.8 | N40: 0.18539372 | O40: 0.15155825 | P40: =(O40-$B$3)/N40 -> 0.58933089
A41: 44771 | B41: 478.9 | C41: 263.37 | E41: =B41/B42-1 -> 0.0006895543 | F41: =C41/C42-1 -> 0.066793584 | G41: =E41*$B$4+F41*$B$5 -> 0.033741569 | M41: 0.85 | N41: 0.19139861 | O41: 0.15216603 | P41: =(O41-$B$3)/N41 -> 0.57401688
...

Sheet SPY&BETA
A1: Price History: SPY-US
A3: Date | B3: SPY Price | C3: NOC Price | D3: MCD Price | F3: SPY Return | G3: NOC Return | H3: MCD Return | L3: NOC | M3: MCD
A4: 45747 | B4: 559.39 | C4: 512.01 | D4: 312.37 | F4: =B4/B5-1 -> -0.058551281 | G4: =C4/C5-1 -> 0.10887079 | H4: =D4/D5-1 -> 0.013102844 | K4: Intercept | L4: =INTERCEPT(G4:G122,$F$4:$F$122) -> 0.0078783029 | M4: =INTERCEPT(H4:H122,$F$4:$F$122) -> 0.0054283078
A5: 45716 | B5: 594.18 | C5: 461.74 | D5: 308.33 | F5: =B5/B6-1 -> -0.012694826 | G5: =C5/C6-1 -> -0.05239395 | H5: =D5/D6-1 -> 0.067994458 | K5: Beta | L5: =SLOPE(G4:G122,$F$4:$F$122) -> 0.44226711 | M5: =SLOPE(H4:H122,$F$4:$F$122) -> 0.60938812
A6: 45688 | B6: 601.82 | C6: 487.27 | D6: 288.7 | F6: =B6/B7-1 -> 0.026856402 | G6: =C6/C7-1 -> 0.038313197 | H6: =D6/D7-1 -> -0.0041050053 | K6: R-squared | L6: =RSQ(G4:G122,$F$4:$F$122) -> 0.10489527 | M6: =RSQ(H4:H122,$F$4:$F$122) -> 0.30479072
A7: 45657 | B7: 586.08 | C7: 469.29 | D7: 289.89 | F7: =B7/B8-1 -> -0.027333831 | G7: =C7/C8-1 -> -0.041580721 | H7: =D7/D8-1 -> -0.020674977
A8: 45625 | B8: 602.55 | C8: 489.65 | D8: 296.01 | F8: =B8/B9-1 -> 0.059633512 | G8: =C8/C9-1 -> -0.038053515 | H8: =D8/D9-1 -> 0.013351135
A9: 45596 | B9: 568.64 | C9: 509.02 | D9: 292.11 | F9: =B9/B10-1 -> -0.0089235917 | G9: =C9/C10-1 -> -0.036074763 | H9: =D9/D10-1 -> -0.040721159
A10: 45565 | B10: 573.76 | C10: 528.07 | D10: 304.51 | F10: =B10/B11-1 -> 0.017882487 | G10: =C10/C11-1 -> 0.0092888133 | H10: =D10/D11-1 -> 0.054908889
A11: 45534 | B11: 563.68 | C11: 523.21 | D11: 288.66 | F11: =B11/B12-1 -> 0.023365589 | G11: =C11/C12-1 -> 0.08029815 | H11: =D11/D12-1 -> 0.087641296
A12: 45504 | B12: 550.81 | C12: 484.32 | D12: 265.4 | F12: =B12/B13-1 -> 0.012109074 | G12: =C12/C13-1 -> 0.11095309 | H12: =D12/D13-1 -> 0.041437765
A13: 45471 | B13: 544.22 | C13: 435.95 | D13: 254.84 | F13: =B13/B14-1 -> 0.031951002 | G13: =C13/C14-1 -> -0.032877077 | H13: =D13/D14-1 -> -0.01564371
A14: 45443 | B14: 527.37 | C14: 450.77 | D14: 258.89 | F14: =B14/B15-1 -> 0.050579704 | G14: =C14/C15-1 -> -0.070634806 | H14: =D14/D15-1 -> -0.051823909
A15: 45412 | B15: 501.98 | C15: 485.03 | D15: 273.04 | F15: =B15/B16-1 -> -0.040319651 | G15: =C15/C16-1 -> 0.013307985 | H15: =D15/D16-1 -> -0.031601348
A16: 45379 | B16: 523.07 | C16: 478.66 | D16: 281.95 | F16: =B16/B17-1 -> 0.029503228 | G16: =C16/C17-1 -> 0.038262982 | H16: =D16/D17-1 -> -0.035342822
A17: 45351 | B17: 508.08 | C17: 461.02 | D17: 292.28 | F17: =B17/B18-1 -> 0.052186879 | G17: =C17/C18-1 -> 0.031918704 | H17: =D17/D18-1 -> -0.0015031429
A18: 45322 | B18: 482.88 | C18: 446.76 | D18: 292.72 | F18: =B18/B19-1 -> 0.015926448 | G18: =C18/C19-1 -> -0.045670099 | H18: =D18/D19-1 -> -0.012782031
... A40: 44651 | B40: 451.64 | C40: 447.22 | D40: 247.28 | F40: =B40/B41-1 -> 0.034376932 | G40: =C40/C41-1 -> 0.011489573 | H40: =D40/D41-1 -> 0.010254525
A41: 44620 | B41: 436.63 | C41: 442.14 | D41: 244.77 | F41: =B41/B42-1 -> -0.029517015 | G41: =C41/C42-1 -> 0.19529603 | H41: =D41/D42-1 -> -0.05658123 | J41: Correl.Matrix
A42: 44592 | B42: 449.91 | C42: 369.9 | D42: 259.45 | F42: =B42/B43-1 -> -0.052741283 | G42: =C42/C43-1 -> -0.044358901 | H42: =D42/D43-1 -> -0.03215578 | L42: SPY Return | M42: NOC Return | N42: MCD Return
A43: 44561 | B43: 474.96 | C43: 387.07 | D43: 268.07 | F43: =B43/B44-1 -> 0.04258495 | G43: =C43/C44-1 -> 0.10971904 | H43: =D43/D44-1 -> 0.095952576 | K43: SPY Return | L43: =CORREL($F$4:$F$122,F4:F122) -> 1 | M43: =CORREL($F$4:$F$122,G4:G122) -> 0.3238754 | N43: =CORREL($F$4:$F$122,H4:H122) -> 0.55207855
A44: 44530 | B44: 455.56 | C44: 348.8 | D44: 244.6 | F44: =B44/B45-1 -> -0.0080348394 | G44: =C44/C45-1 -> -0.023570909 | H44: =D44/D45-1 -> -0.0038688658 | K44: NOC Return | L44: =CORREL($G$4:$G$122,F4:F122) -> 0.3238754 | M44: =CORREL($G$4:$G$122,G4:G122) -> 1 | N44: =CORREL($G$4:$G$122,H4:H122) -> 0.39119075
A45: 44498 | B45: 459.25 | C45: 357.22 | D45: 245.55 | F45: =B45/B46-1 -> 0.070163583 | G45: =C45/C46-1 -> -0.0081354991 | H45: =D45/D46-1 -> 0.018414831 | K45: MCD Return | L45: =CORREL($H$4:$H$122,F4:F122) -> 0.55207855 | M45: =CORREL($H$4:$H$122,G4:G122) -> 0.39119075 | N45: =CORREL($H$4:$H$122,H4:H122) -> 1
A46: 44469 | B46: 429.14 | C46: 360.15 | D46: 241.11 | F46: =B46/B47-1 -> -0.049650102 | G46: =C46/C47-1 -> -0.020533043 | H46: =D46/D47-1 -> 0.01537101
A47: 44439 | B47: 451.56 | C47: 367.7 | D47: 237.46 | F47: =B47/B48-1 -> 0.029759869 | G47: =C47/C48-1 -> 0.012891852 | H47: =D47/D48-1 -> -0.021630753
A48: 44407 | B48: 438.51 | C48: 363.02 | D48: 242.71 | F48: =B48/B49-1 -> 0.024412466 | G48: =C48/C49-1 -> -0.0011281402 | H48: =D48/D49-1 -> 0.050738127 | J48: Covar.Matrix
A49: 44377 | B49: 428.06 | C49: 363.43 | D49: 230.99 | F49: =B49/B50-1 -> 0.01909342 | G49: =C49/C50-1 -> -0.0066690354 | H49: =D49/D50-1 -> -0.012398991 | L49: SPY Return | M49: NOC Return | N49: MCD Return
A50: 44344 | B50: 420.04 | C50: 365.87 | D50: 233.89 | F50: =B50/B51-1 -> 0.0065660197 | G50: =C50/C51-1 -> 0.032248053 | H50: =D50/D51-1 -> -0.0092765164 | K50: SPY Return | L50: =_xlfn.COVARIANCE.P($F$4:$F$122,F4:F122) -> 0.0020017848 | M50: =_xlfn.COVARIANCE.P($F$4:$F$122,G4:G122) -> 0.00088532359 | N50: =_xlfn.COVARIANCE.P($F$4:$F$122,H4:H122) -> 0.0012198639
A51: 44316 | B51: 417.3 | C51: 354.44 | D51: 236.08 | F51: =B51/B52-1 -> 0.052910453 | G51: =C51/C52-1 -> 0.09516747 | H51: =D51/D52-1 -> 0.053270278 | K51: NOC Return | L51: =_xlfn.COVARIANCE.P($G$4:$G$122,F4:F122) -> 0.00088532359 | M51: =_xlfn.COVARIANCE.P($G$4:$G$122,G4:G122) -> 0.003732766 | N51: =_xlfn.COVARIANCE.P($G$4:$G$122,H4:H122) -> 0.0011803363
A52: 44286 | B52: 396.33 | C52: 323.64 | D52: 224.14 | F52: =B52/B53-1 -> 0.041986539 | G52: =C52/C53-1 -> 0.10964822 | H52: =D52/D53-1 -> 0.087319298 | K52: MCD Return | L52: =_xlfn.COVARIANCE.P($H$4:$H$122,F4:F122) -> 0.0012198639 | M52: =_xlfn.COVARIANCE.P($H$4:$H$122,G4:G122) -> 0.0011803363 | N52: =_xlfn.COVARIANCE.P($H$4:$H$122,H4:H122) -> 0.0024389541
A53: 44253 | B53: 380.36 | C53: 291.66 | D53: 206.14 | F53: =B53/B54-1 -> 0.02780555 | G53: =C53/C54-1 -> 0.017619762 | H53: =D53/D54-1 -> -0.0081793687
A54: 44225 | B54: 370.07 | C54: 286.61 | D54: 207.84 | F54: =B54/B55-1 -> -0.010190435 | G54: =C54/C55-1 -> -0.059431609 | H54: =D54/D55-1 -> -0.031410197
A55: 44196 | B55: 373.88 | C55: 304.72 | D55: 214.58 | F55: =B55/B56-1 -> 0.032646523 | G55: =C55/C56-1 -> 0.0081386885 | H55: =D55/D56-1 -> -0.013153054
A56: 44165 | B56: 362.06 | C56: 302.26 | D56: 217.44 | F56: =B56/B57-1 -> 0.10877687 | G56: =C56/C57-1 -> 0.042923194 | H56: =D56/D57-1 -> 0.02084507
A57: 44134 | B57: 326.54 | C57: 289.82 | D57: 213 | F57: =B57/B58-1 -> -0.02493356 | G57: =C57/C58-1 -> -0.081365495 | H57: =D57/D58-1 -> -0.029568545
A58: 44104 | B58: 334.89 | C58: 315.49 | D58: 219.49 | F58: =B58/B59-1 -> -0.041281383 | G58: =C58/C59-1 -> -0.079157059 | H58: =D58/D59-1 -> 0.02795991
A59: 44074 | B59: 349.31 | C59: 342.61 | D59: 213.52 | F59: =B59/B60-1 -> 0.069796643 | G59: =C59/C60-1 -> 0.05415218 | H59: =D59/D60-1 -> 0.099032324
A60: 44043 | B60: 326.52 | C60: 325.01 | D60: 194.28 | F60: =B60/B61-1 -> 0.058892204 | G60: =C60/C61-1 -> 0.057149362 | H60: =D60/D61-1 -> 0.053179379
A61: 44012 | B61: 308.36 | C61: 307.44 | D61: 184.47 | F61: =B61/B62-1 -> 0.013275499 | G61: =C61/C62-1 -> -0.082816229 | H61: =D61/D62-1 -> -0.0099291541
A62: 43980 | B62: 304.32 | C62: 335.2 | D62: 186.32 | F62: =B62/B63-1 -> 0.047645277 | G62: =C62/C63-1 -> 0.013699459 | H62: =D62/D63-1 -> -0.0066112177
...

Sheet 10-year_Bond
A1: FRED Graph Observations
A2: Federal Reserve Economic Data, Federal Reserve Bank of St. Louis
A3: Link: https://fred.stlouisfed.org
A4: Help: https://fredhelp.stlouisfed.org
A5: This data may be copyrighted. Please refer to the Terms of Use: https://fred.stlouisfed.org/legal#fred-terms-faq
A6: File Created: 2025-04-07 5:57 pm CDT
A8: DGS10 | B8: Market Yield on U.S. Treasury Securities at 10-Year Constant Maturity, Quoted on an Investment Basis, Percent, Monthly, Not Seasonally Adjusted | C8: Data Updated: 2025-04-07
A10: Link | B10: https://fred.stlouisfed.org/series/DGS10#
A12: Montley Returns
A13: observation_date | B13: DGS10
A14: 45717 | B14: 0.0423
A15: 45689 | B15: 0.0424
A16: 45658 | B16: 0.0458
A17: 45627 | B17: 0.0458
A18: 45597 | B18: 0.0418
A19: 45566 | B19: 0.0428
A20: 45536 | B20: 0.0381
A21: 45505 | B21: 0.0391
A22: 45474 | B22: 0.0409
A23: 45444 | B23: 0.0436
A24: 45413 | B24: 0.0451
A25: 45383 | B25: 0.0469
... A134: 42064 | B134: 0.0194

Sheet ReadyToUse
B3: NOC | C3: MCD | D3: LMT | E3: KO | F3: KR | G3: RTX
A4: Analysis (10Y) | B4: ='SPY&BETA'!L5 -> 0.44226711 | C4: ='SPY&BETA'!M5 -> 0.60938812 | D4: ='SPY&BETA'!N5 -> 0 | E4: ='SPY&BETA'!O5 -> 0 | F4: ='SPY&BETA'!P5 -> 0 | G4: ='SPY&BETA'!Q5 -> 0
A5: MarketWatch | B5: 0.34 | C5: 0.5 | D5: 0.36 | E5: 0.46 | F5: 0.19 | G5: 0.78
A6: Factset (5Y Raw) | B6: 0.34 | C6: 0.5 | D6: 0.37 | E6: 0.45 | F6: 0.46 | G6: 0.78
A7: Yahoo (5Y Montley) | B7: 0.19 | C7: 0.62 | D7: 0.39 | E7: 0.45 | F7: 0.59 | G7: 0.26
A11: Correl.Matrix
C12: SPY Return | D12: NOC Return | E12: MCD Return | F12: LMT Return | G12: KO Return | H12: KR
B13: SPY Return | C13: 1 | D13: 0.3238754 | E13: 0.55207855 | F13: 0.44235791 | G13: 0.49488651 | H13: 0.30415281
B14: NOC Return | C14: 0.3238754 | D14: 1 | E14: 0.39119075 | F14: 0.77716324 | G14: 0.38167323 | H14: 0.1806673
B15: MCD Return | C15: 0.55207855 | D15: 0.39119075 | E15: 1 | F15: 0.47757243 | G15: 0.64391242 | H15: 0.18447678
B16: LMT Return | C16: 0.44235791 | D16: 0.77716324 | E16: 0.47757243 | F16: 1 | G16: 0.47161583 | H16: 0.21151865
B17: KO Return | C17: 0.49488651 | D17: 0.38167323 | E17: 0.64391242 | F17: 0.47161583 | G17: 1 | H17: 0.16758042
B18: KR | C18: 0.30415281 | D18: 0.1806673 | E18: 0.18447678 | F18: 0.21151865 | G18: 0.16758042 | H18: 1
A23: Covar.Matrix
C24: SPY Return | D24: NOC Return | E24: MCD Return | F24: LMT Return | G24: KO Return | H24: KR
B25: SPY Return | C25: 0.0020017848 | D25: 0.00088532359 | E25: 0.0012198639 | F25: 0.0012084811 | G25: 0.0010216922 | H25: 0.0010327473
B26: NOC Return | C26: 0.00088532359 | D26: 0.003732766 | E26: 0.0011803363 | F26: 0.0028992455 | G26: 0.0010760014 | H26: 0.00083769997
B27: MCD Return | C27: 0.0012198639 | D27: 0.0011803363 | E27: 0.0024389541 | F27: 0.0014401192 | G27: 0.0014673522 | H27: 0.00069141226
B28: LMT Return | C28: 0.0012084811 | D28: 0.0028992455 | E28: 0.0014401192 | F28: 0.0037283333 | G28: 0.0013287751 | H28: 0.00098016589
B29: KO Return | C29: 0.0010216922 | D29: 0.0010760014 | E29: 0.0014673522 | F29: 0.0013287751 | G29: 0.0021291757 | H29: 0.0005868439
B30: KR | C30: 0.0010327473 | D30: 0.00083769997 | E30: 0.00069141226 | F30: 0.00098016589 | G30: 0.0005868439 | H30: 0.005759531
