Workbook

Sheet GT-US-IS
A1: Goodyear Tire & Rubber Company (GT)
A2: =Beta_Calc!B4 -> 9
A5: Goodyear Tire & Rubber Company
A6: GT 382550101 2378200 NASDAQ Common stock
A7: Source: FactSet Fundamentals
B8: DEC '15 | C8: DEC '16 | D8: DEC '17 | E8: DEC '18 | F8: DEC '19 | G8: DEC '20 | H8: DEC '21 | I8: DEC '22 | J8: DEC '23 | K8: DEC '24
D9: Restate
A10: Sales | B10: 16443 | C10: 15158 | D10: 15377 | E10: 15475 | F10: 14745 | G10: 12321 | H10: 17478 | I10: 20805 | J10: 20066 | K10: 18878
A11: Cost of Goods Sold (COGS) incl. D&A | B11: 11802 | C11: 10570 | D11: 11234 | E11: 11529 | F11: 11171 | G11: 9846 | H11: 13264 | I11: 16556 | J11: 16138 | K11: 14897
A12: COGS excluding D&A | B12: 11104 | C12: 9843 | D12: 10453 | E12: 10751 | F12: 10376 | G12: 8987 | H12: 12381 | I12: 15592 | J12: 15137 | K12: 13848
A13: Depreciation & Amortization Expense | B13: 698 | C13: 727 | D13: 781 | E13: 778 | F13: 795 | G13: 859 | H13: 883 | I13: 964 | J13: 1001 | K13: 1049
A14: Depreciation | B14: 697 | C14: 726 | D14: 779 | E14: 776 | F14: 793 | G14: 857 | H14: 862 | I14: 929 | J14: 968 | K14: 1017
A15: Amortization of Intangibles | B15: 1 | C15: 1 | D15: 2 | E15: 2 | F15: 2 | G15: 2 | H15: 21 | I15: 35 | J15: 33 | K15: 32
A16: Gross Income | B16: 4641 | C16: 4588 | D16: 4143 | E16: 3946 | F16: 3574 | G16: 2475 | H16: 4214 | I16: 4249 | J16: 3928 | K16: 3981
A17: SG&A Expense | B17: 2990 | C17: 2795 | D17: 2740 | E17: 2736 | F17: 2753 | G17: 2582 | H17: 3195 | I17: 3299 | J17: 3477 | K17: 3184
A18: Research & Development | B18: 382 | C18: 388 | D18: 406 | E18: 424 | F18: 430 | G18: 390 | H18: 496 | I18: 501 | J18: 461 | K18: 426
A19: Other SG&A | B19: 2608 | C19: 2407 | D19: 2334 | E19: 2312 | F19: 2323 | G19: 2192 | H19: 2699 | I19: 2798 | J19: 3016 | K19: 2758
A20: Other Operating Expense | B20: 0 | C20: 0 | D20: 0 | E20: 0 | F20: 0 | G20: 0 | H20: 0 | I20: 0 | J20: -202 | K20: 24
A21: EBIT (Operating Income) | B21: 1651 | C21: 1793 | D21: 1403 | E21: 1210 | F21: 821 | G21: -107 | H21: 1019 | I21: 950 | J21: 653 | K21: 773
... A28: Unusual Expense - Net | B28: 675 | C28: 201 | D28: 244 | E28: -286 | F28: 234 | G28: 691 | H28: 28 | I28: 2 | J28: 684 | K28: -8
A29: Impairments | G29: 330 | H29: 0 | I29: 0 | J29: 230 | K29: 125
A30: Goodwill | B30: 0 | C30: 0 | D30: 0 | E30: 0 | F30: 0 | G30: 330 | H30: 0 | I30: 0 | J30: 230 | K30: 125
A31: Exceptional Provisions | B31: -25 | C31: -27
A32: Restructuring Expense | B32: 766 | C32: 210 | D32: 175 | E32: -224 | F32: 220 | G32: 264 | H32: 133 | I32: 129 | J32: 456 | K32: -60
A33: Legal Claim Expense | B33: 4 | C33: 10 | E33: 9 | F33: 11 | G33: 10 | H33: 0 | I33: 14 | J33: 6 | K33: 3
A34: Unrealized Valuation Gain/Loss | B34: 78 | D34: -55 | E34: 83 | F34: 22 | G34: -87 | H34: 35 | I34: 35 | J34: 8 | K34: 76
A35: Investments | B35: 78
A36: Hedges/Derivatives | D36: -55 | E36: 83 | F36: 22 | G36: -87 | H36: 35 | I36: 35 | J36: 8 | K36: 76
A37: Excpl Chrgs - Others | B37: 8 | C37: 8 | D37: 14 | E37: 12 | F37: 25 | G37: 0 | H37: -70 | I37: -106
A38: Restructuring of Debt | C38: -12
A39: Calamitous Events | D39: 14 | E39: 12 | F39: 25 | G39: 0
A40: Accelerated Depreciation | B40: 8 | C40: 20 | H40: -1 | I40: -37
A41: Other Unusual Expense | H41: -69 | I41: -69
A42: Pretax Income | B42: 608 | C42: 1207 | D42: 878 | E42: 1011 | F42: 177 | G42: -1140 | H42: 513 | I42: 399 | J42: -677 | K42: 155
A43: Income Taxes | B43: 232 | C43: -77 | D43: 513 | E43: 303 | F43: 474 | G43: 110 | H43: -267 | I43: 190 | J43: 10 | K43: 95
A44: Income Taxes - Current Domestic | B44: -1 | C44: -23 | D44: -19 | E44: -16 | F44: 17 | G44: -8 | H44: 38 | I44: 12 | J44: 63 | K44: -29
A45: Income Taxes - Current Foreign | B45: 154 | C45: 175 | D45: 166 | E45: 188 | F45: 134 | G45: 95 | H45: 166 | I45: 150 | J45: 177 | K45: 189
A46: Income Taxes - Deferred Domestic | B46: 74 | C46: 99 | D46: 374 | E46: 125 | F46: 170 | G46: 54 | H46: -448 | I46: -18 | J46: -168 | K46: -96
A47: Income Taxes - Deferred Foreign | B47: 5 | C47: -328 | D47: -8 | E47: 6 | F47: 153 | G47: -31 | H47: -23 | I47: 46 | J47: -62 | K47: 31
A48: Consolidated Net Income | B48: 376 | C48: 1284 | D48: 365 | E48: 708 | F48: -297 | G48: -1250 | H48: 780 | I48: 209 | J48: -687 | K48: 60
...

Sheet GT-US-BS
A1: Goodyear Tire & Rubber Company (GT)
A2: $10.70
A5: Goodyear Tire & Rubber Company
A6: GT 382550101 2378200 NASDAQ Common stock
A7: Source: FactSet Fundamentals
B8: DEC '15 | C8: DEC '16 | D8: DEC '17 | E8: DEC '18 | F8: DEC '19 | G8: DEC '20 | H8: DEC '21 | I8: DEC '22 | J8: DEC '23 | K8: DEC '24
D9: Restate
A10: Assets
A11: Cash & Short-Term Investments | B11: 1476 | C11: 1132 | D11: 1110 | E11: 873 | F11: 974 | G11: 1624 | H11: 1164 | I11: 1301 | J11: 985 | K11: 864
A12: Cash Only | B12: 1476 | C12: 1132 | D12: 1110 | E12: 873 | F12: 974 | G12: 1624 | H12: 1164 | I12: 1301 | J12: 985 | K12: 864
A13: Short-Term Receivables | B13: 2033 | C13: 1769 | D13: 2025 | E13: 2030 | F13: 1941 | G13: 1691 | H13: 2387 | I13: 2610 | J13: 2731 | K13: 2482
A14: Accounts Receivables, Net | B14: 2033 | C14: 1769 | D14: 2025 | E14: 2030 | F14: 1938 | G14: 1690 | H14: 2376 | I14: 2604 | J14: 2718 | K14: 2450
A15: Accounts Receivables, Gross | B15: 2138 | C15: 1870 | D15: 2141 | E15: 2143 | F15: 2049 | G15: 1840 | H15: 2499 | I15: 2716 | J15: 2820 | K15: 2534
A16: Bad Debt/Doubtful Accounts | B16: -105 | C16: -101 | D16: -116 | E16: -113 | F16: -111 | G16: -150 | H16: -123 | I16: -112 | J16: -102 | K16: -84
A17: Other Receivables | B17: 0 | C17: 0 | D17: 0 | E17: 0 | F17: 3 | G17: 1 | H17: 11 | I17: 6 | J17: 13 | K17: 32
A18: Inventories | B18: 2464 | C18: 2627 | D18: 2787 | E18: 2856 | F18: 2851 | G18: 2153 | H18: 3594 | I18: 4571 | J18: 3698 | K18: 3597
A19: Finished Goods | B19: 1907 | C19: 2060 | D19: 2179 | E19: 2135 | F19: 2178 | G19: 1493 | H19: 2445 | I19: 3193 | J19: 2707 | K19: 2629
A20: Work in Progress | B20: 138 | C20: 131 | D20: 142 | E20: 152 | F20: 143 | G20: 143 | H20: 191 | I20: 187 | J20: 206 | K20: 213
A21: Raw Materials | B21: 419 | C21: 436 | D21: 466 | E21: 569 | F21: 530 | G21: 517 | H21: 958 | I21: 1191 | J21: 785 | K21: 755
A22: Other Current Assets | B22: 168 | C22: 190 | D22: 157 | E22: 166 | F22: 168 | G22: 152 | H22: 186 | I22: 183 | J22: 236 | K22: 689
... A30: Construction in Progress | B30: 783 | C30: 887 | D30: 721 | E30: 655 | F30: 682 | G30: 737 | H30: 785 | I30: 1173 | J30: 1340 | K30: 1300
A31: Leases | B31: 195 | C31: 280
A32: Other Property, Plant & Equipment | D32: 254 | E32: 262 | F32: 276 | G32: 269 | H32: 300 | I32: 302 | J32: 371 | K32: 344
A33: Operating Lease Right-of-Use Assets | F33: 855 | G33: 851 | H33: 981 | I33: 976 | J33: 985 | K33: 951
A34: Accumulated Depreciation | B34: 8637 | C34: 9125 | D34: 10078 | E34: 10161 | F34: 10488 | G34: 10991 | H34: 11130 | J34: 12472 | K34: 12212
A35: Total Long-Term Investments | B35: 0 | C35: 0 | D35: 0 | E35: 2 | F35: 263 | G35: 77 | H35: 86 | I35: 70 | J35: 22 | K35: 110
A36: LT Investment - Affiliate Companies | D36: 0 | E36: 0 | F36: 262 | G36: 77 | H36: 72 | I36: 60 | J36: 0 | K36: 0
A37: Other Long-Term Investments | B37: 0 | C37: 0 | D37: 0 | E37: 2 | F37: 1 | G37: 0 | H37: 14 | I37: 10 | J37: 22 | K37: 110
A38: Intangible Assets | B38: 693 | C38: 671 | D38: 734 | E38: 705 | F38: 702 | G38: 543 | H38: 2043 | I38: 2018 | J38: 1750 | K38: 1561
A39: Goodwill | B39: 555 | C39: 535 | D39: 595 | E39: 569 | F39: 565 | G39: 408 | H39: 1004 | I39: 1014 | J39: 781 | K39: 756
A40: Other Intangible Assets | B40: 138 | C40: 136 | D40: 139 | E40: 136 | F40: 137 | G40: 135 | H40: 1039 | I40: 1004 | J40: 969 | K40: 805
A41: Deferred Tax Assets | B41: 2141 | C41: 2414 | D41: 2008 | E41: 1847 | F41: 1527 | G41: 1467 | H41: 1596 | I41: 1443 | J41: 1630 | K41: 1686
A42: Other Assets | B42: 687 | C42: 668 | D42: 792 | E42: 1134 | F42: 696 | G42: 875 | H42: 1020 | I42: 965 | J42: 1053 | K42: 942
A43: Tangible Other Assets | B43: 687 | C43: 668 | D43: 792 | E43: 1134 | F43: 696 | G43: 875 | H43: 1020 | I43: 965 | J43: 1053 | K43: 942
A44: Total Assets | B44: 16439 | C44: 16511 | D44: 17064 | E44: 16872 | F44: 17185 | G44: 16506 | H44: 21402 | I44: 22431 | J44: 21582 | K44: 20964
A45: Liabilities & Shareholders' Equity
A46: Current
A47: ST Debt & Curr. Portion LT Debt | B47: 636 | C47: 681 | D47: 653 | E47: 653 | F47: 1109 | G47: 756 | H47: 953 | I47: 822 | J47: 993 | K47: 1590
A48: Accounts Payable | B48: 2769 | C48: 2589 | D48: 2807 | E48: 2920 | F48: 2908 | G48: 2945 | H48: 4148 | I48: 4803 | J48: 4326 | K48: 4052
A49: Other Current Liabilities | B49: 1552 | C49: 1547 | D49: 1565 | E49: 1208 | F49: 1270 | G49: 1405 | H49: 1511 | I49: 1515 | J49: 1828 | K49: 1695
...

Sheet GT-US-CF
A1: Goodyear Tire & Rubber Company (GT)
A2: $10.71
A5: Goodyear Tire & Rubber Company
A6: GT 382550101 2378200 NASDAQ Common stock
A7: Source: FactSet Fundamentals
B8: DEC '15 | C8: DEC '16 | D8: DEC '17 | E8: DEC '18 | F8: DEC '19 | G8: DEC '20 | H8: DEC '21 | I8: DEC '22 | J8: DEC '23 | K8: DEC '24
D9: Restate
A10: Operating Activities
A11: Net Income / Starting Line | B11: 376 | C11: 1284 | D11: 365 | E11: 708 | F11: -297 | G11: -1250 | H11: 780 | I11: 209 | J11: -687 | K11: 60
A12: Depreciation, Depletion & Amortization | B12: 698 | C12: 727 | D12: 781 | E12: 778 | F12: 795 | G12: 859 | H12: 883 | I12: 964 | J12: 1001 | K12: 1049
A13: Depreciation and Depletion | B13: 697 | C13: 726 | D13: 777 | E13: 776 | F13: 793 | G13: 857 | H13: 862 | I13: 928 | J13: 968 | K13: 1017
A14: Amortization of Intangible Assets | B14: 1 | C14: 1 | D14: 2 | E14: 2 | F14: 2 | G14: 2 | H14: 21 | I14: 35 | J14: 33 | K14: 32
A15: Deferred Taxes & Investment Tax Credit | B15: 79 | C15: -229 | D15: 366 | E15: 131 | F15: 323 | G15: 23 | H15: -471 | I15: 28 | J15: -230 | K15: -65
A16: Deferred Taxes | B16: 79 | C16: -229 | D16: 366 | E16: 131 | F16: 323 | G16: 23 | H16: -471 | I16: 28 | J16: -230 | K16: -65
A17: Other Funds | B17: 449 | C17: 50 | D17: -83 | E17: -440 | F17: 97 | G17: 296 | H17: -17 | I17: 13 | J17: 554 | K17: -164
A18: Funds from Operations | B18: 1602 | C18: 1832 | D18: 1429 | E18: 1177 | F18: 918 | G18: -72 | H18: 1175 | I18: 1214 | J18: 638 | K18: 880
A19: Changes in Working Capital | B19: 85 | C19: -328 | D19: -271 | E19: -261 | F19: 289 | G19: 1187 | H19: -113 | I19: -693 | J19: 394 | K19: -182
A20: Receivables | B20: -31 | C20: 211 | D20: -147 | E20: -172 | F20: 71 | G20: 132 | H20: -300 | I20: -333 | J20: -59 | K20: 127
A21: Inventories | B21: -89 | C21: -172 | D21: -44 | E21: -171 | F21: 6 | G21: 713 | H21: -982 | I21: -1042 | J21: 908 | K21: -122
A22: Accounts Payable | B22: 78 | C22: -156 | D22: 85 | E22: 223 | F22: 5 | G22: 26 | H22: 923 | I22: 686 | J22: -550 | K22: -87
... A25: Net Operating Cash Flow | B25: 1687 | C25: 1504 | D25: 1158 | E25: 916 | F25: 1207 | G25: 1115 | H25: 1062 | I25: 521 | J25: 1032 | K25: 698
A26: Investing Activities
A27: Capital Expenditures | B27: -983 | C27: -996 | D27: -881 | E27: -811 | F27: -770 | G27: -647 | H27: -981 | I27: -1061 | J27: -1050 | K27: -1188
A28: Capital Expenditures (Fixed Assets) | B28: -983 | C28: -996 | D28: -881 | E28: -811 | F28: -770 | G28: -647 | H28: -981 | I28: -1061 | J28: -1050 | K28: -1188
A29: Net Assets from Acquisitions | B29: -320 | C29: -11 | D29: -7 | E29: -31 | F29: -26 | G29: -10 | H29: -1869 | I29: -9 | J29: -3 | K29: -8
A30: Sale of Fixed Assets & Businesses | B30: 62 | C30: 35 | D30: 12 | E30: 2 | F30: 12 | G30: 0 | H30: 14 | I30: 52 | J30: 16 | K30: 115
A31: Purchase/Sale of Investments | B31: -14 | C31: -6 | D31: 0 | E31: 0 | F31: -7 | G31: 0 | H31: 7 | I31: 32 | J31: -8 | K31: 6
A32: Purchase of Investments | B32: 83 | C32: 72 | D32: 83 | E32: 68 | F32: 113 | G32: 96 | H32: 118 | I32: 75 | J32: 108 | K32: 0
A33: Sale/Maturity of Investments | B33: 69 | C33: 66 | D33: 83 | E33: 68 | F33: 106 | G33: 96 | H33: 125 | I33: 107 | J33: 100 | K33: 6
A34: Other Funds | B34: -7 | C34: -6 | D34: -10 | E34: -58 | F34: -35 | G34: -20 | H34: 23 | I34: 63 | J34: 7 | K34: 62
A35: Other Uses | B35: -7 | C35: -6 | D35: -10 | E35: -58 | F35: -35 | G35: -20 | I35: -45 | J35: -92 | K35: -16
A36: Other Sources | B36: 0 | C36: 0 | E36: 0 | F36: 0 | G36: 0 | H36: 23 | I36: 108 | J36: 99 | K36: 78
A37: Net Investing Cash Flow | B37: -1262 | C37: -984 | D37: -886 | E37: -898 | F37: -826 | G37: -677 | H37: -2806 | I37: -923 | J37: -1038 | K37: -1013
A38: Financing Activities
A39: Cash Dividends Paid | B39: -68 | C39: -82 | D39: -110 | E39: -138 | F39: -148 | G39: -37 | H39: 0 | I39: 0 | J39: 0 | K39: 0
A40: Common Dividends | B40: -68 | C40: -82 | D40: -110 | E40: -138 | F40: -148 | G40: -37 | H40: 0 | I40: 0 | J40: 0 | K40: 0
A41: Change in Capital Stock | B41: -127 | C41: -487 | D41: -386 | E41: -216 | F41: 1 | G41: 0 | H41: 9 | I41: -6 | J41: -2 | K41: -3
A42: Repurchase of Common & Preferred Stk. | B42: -180 | C42: -500 | D42: -400 | E42: -220 | F42: 0 | G42: 0 | H42: 0 | I42: -6 | J42: -2 | K42: -3
A43: Sale of Common & Preferred Stock | B43: 53 | C43: 13 | D43: 14 | E43: 4 | F43: 1 | G43: 0 | H43: 9 | I43: 0 | J43: 0 | K43: 0
A44: Proceeds from Sale of Stock | B44: 53 | C44: 13 | D44: 14 | E44: 4 | F44: 1 | G44: 0 | H44: 9 | I44: 0 | J44: 0 | K44: 0
...

Sheet Beta_Calc
A1: Price History: GT-US
A3: Date | B3: Price | C3: Returns | E3: Date | F3: Price | G3: Returns | I3: Beta | J3: =SLOPE(C4:C58,G4:G58) -> 1.5144136
A4: 45657 | B4: 9 | C4: =B4/B5-1 -> -0.16201117 | E4: 45657 | F4: 5881.6276 | G4: =F4/F5-1 -> -0.02499124
A5: 45625 | B5: 10.74 | C5: =B5/B6-1 -> 0.34082397 | E5: 45625 | F5: 6032.3844 | G5: =F5/F6-1 -> 0.057302511
A6: 45596 | B6: 8.01 | C6: =B6/B7-1 -> -0.094915254 | E6: 45596 | F6: 5705.4479 | G6: =F6/F7-1 -> -0.0098979804
A7: 45565 | B7: 8.85 | C7: =B7/B8-1 -> 0.0034013605 | E7: 45565 | F7: 5762.4849 | G7: =F7/F8-1 -> 0.020198234
A8: 45534 | B8: 8.82 | C8: =B8/B9-1 -> -0.24615385 | E8: 45534 | F8: 5648.3972 | G8: =F8/F9-1 -> 0.022833848
A9: 45504 | B9: 11.7 | C9: =B9/B10-1 -> 0.030837004 | E9: 45504 | F9: 5522.3018 | G9: =F9/F10-1 -> 0.0113212
A10: 45471 | B10: 11.35 | C10: =B10/B11-1 -> -0.077985378 | E10: 45471 | F10: 5460.4826 | G10: =F10/F11-1 -> 0.034670776
A11: 45443 | B11: 12.31 | C11: =B11/B12-1 -> 0.029264214 | E11: 45443 | F11: 5277.5073 | G11: =F11/F12-1 -> 0.048020348
A12: 45412 | B12: 11.96 | C12: =B12/B13-1 -> -0.12891479 | E12: 45412 | F12: 5035.6917 | G12: =F12/F13-1 -> -0.041615526
A13: 45379 | B13: 13.73 | C13: =B13/B14-1 -> 0.15572391 | E13: 45379 | F13: 5254.3544 | G13: =F13/F14-1 -> 0.03101973
A14: 45351 | B14: 11.88 | C14: =B14/B15-1 -> -0.14777618 | E14: 45351 | F14: 5096.2695 | G14: =F14/F15-1 -> 0.051721125
A15: 45322 | B15: 13.94 | C15: =B15/B16-1 -> -0.026536313 | E15: 45322 | F15: 4845.6472 | G15: =F15/F16-1 -> 0.015895278
... A58: 44012 | B58: 8.945 | C58: =B58/B59-1 -> 0.17542707 | E58: 44012 | F58: 3100.2851 | G58: =F58/F59-1 -> 0.018388424
A59: 43980 | B59: 7.61 | E59: 43980 | F59: 3044.3052

Sheet Calculations
A1: Year | B1: ='GT-US-IS'!E8 -> DEC '18 | C1: ='GT-US-IS'!F8 -> DEC '19 | D1: ='GT-US-IS'!G8 -> DEC '20 | E1: ='GT-US-IS'!H8 -> DEC '21 | F1: ='GT-US-IS'!I8 -> DEC '22 | G1: ='GT-US-IS'!J8 -> DEC '23 | H1: ='GT-US-IS'!K8 -> DEC '24
A3: Revenue | B3: ='GT-US-IS'!E10 -> 15475 | C3: ='GT-US-IS'!F10 -> 14745 | D3: ='GT-US-IS'!G10 -> 12321 | E3: ='GT-US-IS'!H10 -> 17478 | F3: ='GT-US-IS'!I10 -> 20805 | G3: ='GT-US-IS'!J10 -> 20066 | H3: ='GT-US-IS'!K10 -> 18878
A4: Revenue Growth YOY | C4: =C3/B3-1 -> -0.047172859 | D4: =D3/C3-1 -> -0.16439471 | E4: =E3/D3-1 -> 0.41855369 | F4: =F3/E3-1 -> 0.19035359 | G4: =G3/F3-1 -> -0.035520308 | H4: =H3/G3-1 -> -0.059204625
A5: EBIT | B5: ='GT-US-IS'!E21 -> 1210 | C5: ='GT-US-IS'!F21 -> 821 | D5: ='GT-US-IS'!G21 -> -107 | E5: ='GT-US-IS'!H21 -> 1019 | F5: ='GT-US-IS'!I21 -> 950 | G5: ='GT-US-IS'!J21 -> 653 | H5: ='GT-US-IS'!K21 -> 773
A6: EBIT Margin | B6: =B5/B3 -> 0.07819063 | C6: =C5/C3 -> 0.055679891 | D6: =D5/D3 -> -0.00868436 | E6: =E5/E3 -> 0.058301865 | F6: =F5/F3 -> 0.0456621 | G6: =G5/G3 -> 0.032542609 | H6: =H5/H3 -> 0.040947134
A8: Pre-tax Income | B8: ='GT-US-IS'!E42 -> 1011 | C8: ='GT-US-IS'!F42 -> 177 | D8: ='GT-US-IS'!G42 -> -1140 | E8: ='GT-US-IS'!H42 -> 513 | F8: ='GT-US-IS'!I42 -> 399 | G8: ='GT-US-IS'!J42 -> -677 | H8: ='GT-US-IS'!K42 -> 155
A9: Income Tax | B9: ='GT-US-IS'!E43 -> 303 | C9: ='GT-US-IS'!F43 -> 474 | D9: ='GT-US-IS'!G43 -> 110 | E9: ='GT-US-IS'!H43 -> -267 | F9: ='GT-US-IS'!I43 -> 190 | G9: ='GT-US-IS'!J43 -> 10 | H9: ='GT-US-IS'!K43 -> 95
A10: Tax Rate | B10: =B9/B8 -> 0.29970326 | C10: =C9/C8 -> 2.6779661 | D10: =D9/D8 -> -0.096491228 | E10: =E9/E8 -> -0.52046784 | F10: =F9/F8 -> 0.47619048 | G10: =G9/G8 -> -0.014771049 | H10: =H9/H8 -> 0.61290323
A11: Comments on tax rate | D11: Loss | E11: Outlier | G11: Loss
A13: Depreciation | B13: ='GT-US-IS'!E13 -> 778 | C13: ='GT-US-IS'!F13 -> 795 | D13: ='GT-US-IS'!G13 -> 859 | E13: ='GT-US-IS'!H13 -> 883 | F13: ='GT-US-IS'!I13 -> 964 | G13: ='GT-US-IS'!J13 -> 1001 | H13: ='GT-US-IS'!K13 -> 1049
A14: Depreciation %-of sales | B14: =B13/B3 -> 0.050274637 | C14: =C13/C3 -> 0.053916582 | D14: =D13/D3 -> 0.069718367 | E14: =E13/E3 -> 0.050520655 | F14: =F13/F3 -> 0.046335016 | G14: =G13/G3 -> 0.049885378 | H14: =H13/H3 -> 0.055567327
A16: CAPEX | B16: =-'GT-US-CF'!E27 -> 811 | C16: =-'GT-US-CF'!F27 -> 770 | D16: =-'GT-US-CF'!G27 -> 647 | E16: =-'GT-US-CF'!H27 -> 981 | F16: =-'GT-US-CF'!I27 -> 1061 | G16: =-'GT-US-CF'!J27 -> 1050 | H16: =-'GT-US-CF'!K27 -> 1188
A17: CAPEX %-of Sales | B17: =B16/B3 -> 0.052407108 | C17: =C16/C3 -> 0.052221092 | D17: =D16/D3 -> 0.052511971 | E17: =E16/E3 -> 0.056127703 | F17: =F16/F3 -> 0.050997356 | G17: =G16/G3 -> 0.05232732 | H17: =H16/H3 -> 0.062930395
A19: NWC | B19: ='GT-US-BS'!E14+'GT-US-BS'!E18+'GT-US-BS'!E22-'GT-US-BS'!E48-'GT-US-BS'!E49-'GT-US-BS'!E50-'GT-US-BS'!E51 -> -284 | C19: ='GT-US-BS'!F14+'GT-US-BS'!F18+'GT-US-BS'!F22-'GT-US-BS'!F48-'GT-US-BS'!F49-'GT-US-BS'!F50-'GT-US-BS'!F51 -> -491 | D19: ='GT-US-BS'!G14+'GT-US-BS'!G18+'GT-US-BS'!G22-'GT-US-BS'!G48-'GT-US-BS'!G49-'GT-US-BS'!G50-'GT-US-BS'!G51 -> -1760 | E19: ='GT-US-BS'!H14+'GT-US-BS'!H18+'GT-US-BS'!H22-'GT-US-BS'!H48-'GT-US-BS'!H49-'GT-US-BS'!H50-'GT-US-BS'!H51 -> -1014 | F19: ='GT-US-BS'!I14+'GT-US-BS'!I18+'GT-US-BS'!I22-'GT-US-BS'!I48-'GT-US-BS'!I49-'GT-US-BS'!I50-'GT-US-BS'!I51 -> -475 | G19: ='GT-US-BS'!J14+'GT-US-BS'!J18+'GT-US-BS'!J22-'GT-US-BS'!J48-'GT-US-BS'!J49-'GT-US-BS'!J50-'GT-US-BS'!J51 -> -1330 | H19: ='GT-US-BS'!K14+'GT-US-BS'!K18+'GT-US-BS'!K22-'GT-US-BS'!K48-'GT-US-BS'!K49-'GT-US-BS'!K50-'GT-US-BS'!K51 -> -706
A20: Change NWC | C20: =C19-B19 -> -207 | D20: =D19-C19 -> -1269 | E20: =E19-D19 -> 746 | F20: =F19-E19 -> 539 | G20: =G19-F19 -> -855 | H20: =H19-G19 -> 624
A21: Change in Sales | C21: =C3-B3 -> -730 | D21: =D3-C3 -> -2424 | E21: =E3-D3 -> 5157 | F21: =F3-E3 -> 3327 | G21: =G3-F3 -> -739 | H21: =H3-G3 -> -1188
A22: Change NWC/ Change Sales | C22: =C20/C21 -> 0.28356164 | D22: =D20/D21 -> 0.52351485 | E22: =E20/E21 -> 0.14465775 | F22: =F20/F21 -> 0.16200781 | G22: =G20/G21 -> 1.1569689 | H22: =H20/H21 -> -0.52525253
A24: Risk-Free Rate (Rf) | B24: 0.0458
A25: Beta | B25: =Beta_Calc!J3 -> 1.5144136
A26: MRP | B26: 0.0433
A27: Equity Value | B27: =Beta_Calc!B4*'GT-US-IS'!K58 -> 2592
A28: Debt Value 2024 | B28: ='GT-US-BS'!K47+'GT-US-BS'!K54 -> 8786
A29: Debt Value 2023 | B29: ='GT-US-BS'!J47+'GT-US-BS'!J54 -> 8649
A30: Average Debt | B30: =AVERAGE(B28:B29) -> 8717.5
A31: Weight of Equity | B31: =B27/(B27+B28) -> 0.22780805
A32: Weight of Debt | B32: =B28/(B28+B27) -> 0.77219195
A33: Cost of Equity | B33: =B24+B25*B26 -> 0.11137411
A34: Cost of Debt | B34: ='GT-US-IS'!K26/Calculations!B30 -> 0.071121308
A38: Revenue CAGR (2018–2024) | B38: =(H3/B3)^(1/6)-1 -> 0.033683429
A39: Average EBIT | B39: =AVERAGE(B6:H6) -> 0.043234267
A40: Tax Rate Assumption | B40: 0.25
A41: Median D&A | B41: =MEDIAN(B14:H14) -> 0.050520655
A42: Median CAPEX | B42: =MEDIAN(B17:H17) -> 0.052407108
A43: Final NWC | B43: =AVERAGE(E22,F22) -> 0.15333278
A44: WACC | B44: =B33*B31+B34*B32*(1-B40) -> 0.066561394

Sheet Forecast
A1: Assumptions:
A2: Valuation as of | B2: ='GT-US-BS'!K8 -> DEC '24
A3: Currency | B3: USD
A4: Revenue Growth Rate | B4: =Calculations!B38 -> 0.033683429
A5: EBIT Rate | B5: =Calculations!B39 -> 0.043234267
A6: Tax Rate | B6: =Calculations!B40 -> 0.25
A7: D&A | B7: =Calculations!B41 -> 0.050520655
A8: CAPEX | B8: =Calculations!B42 -> 0.052407108
A9: NWC | B9: =Calculations!B43 -> 0.15333278
A10: WACC | B10: =Calculations!B44 -> 0.066561394
A11: Terminal Grwoth | B11: 0.02
A12: Diluted Shares | B12: ='GT-US-IS'!K58 -> 288
B14: Base Year | C14: 1 | D14: 2 | E14: 3 | F14: 4 | G14: 5
A15: Years | B15: 2024 | C15: 2025 | D15: 2026 | E15: 2027 | F15: 2028 | G15: 2029
A16: Revenue | B16: =Calculations!H3 -> 18878 | C16: =B16*(1+$B$4) -> 19513.876 | D16: =C16*(1+$B$4) -> 20171.17 | E16: =D16*(1+$B$4) -> 20850.604 | F16: =E16*(1+$B$4) -> 21552.924 | G16: =F16*(1+$B$4) -> 22278.9
A17: EBIT | B17: =Calculations!H5 -> 773 | C17: =C16*$B$5 -> 843.66812 | D17: =D16*$B$5 -> 872.08576 | E17: =E16*$B$5 -> 901.46059 | F17: =F16*$B$5 -> 931.82488 | G17: =G16*$B$5 -> 963.21193
A18: NOPAT | B18: =B17*(1-$B$6) -> 579.75 | C18: =C17*(1-$B$6) -> 632.75109 | D18: =D17*(1-$B$6) -> 654.06432 | E18: =E17*(1-$B$6) -> 676.09545 | F18: =F17*(1-$B$6) -> 698.86866 | G18: =G17*(1-$B$6) -> 722.40895
A19: D&A | B19: =Calculations!H13 -> 1049 | C19: =C16*$B$7 -> 985.85378 | D19: =D16*$B$7 -> 1019.0607 | E19: =E16*$B$7 -> 1053.3862 | F19: =F16*$B$7 -> 1088.8678 | G19: =G16*$B$7 -> 1125.5446
A20: CAPEX | B20: =Calculations!H16 -> 1188 | C20: =C16*$B$8 -> 1022.6658 | D20: =D16*$B$8 -> 1057.1127 | E20: =E16*$B$8 -> 1092.7199 | F20: =F16*$B$8 -> 1129.5264 | G20: =G16*$B$8 -> 1167.5727
A21: Change in NWC | C21: =(C16-B16)*$B$9 -> 97.5006 | D21: =(D16-C16)*$B$9 -> 100.78475 | E21: =(E16-D16)*$B$9 -> 104.17953 | F21: =(F16-E16)*$B$9 -> 107.68865 | G21: =(G16-F16)*$B$9 -> 111.31598
A22: Unlevered Free Cash Flows | C22: =C18+C19-C20-C21 -> 498.43847 | D22: =D18+D19-D20-D21 -> 515.22758 | E22: =E18+E19-E20-E21 -> 532.58222 | F22: =F18+F19-F20-F21 -> 550.52141 | G22: =G18+G19-G20-G21 -> 569.06486
A23: Present Values of FCF | C23: =C22/(1+$B$10)^C14 -> 467.33219 | D23: =D22/(1+$B$10)^D14 -> 452.92614 | E23: =E22/(1+$B$10)^E14 -> 438.96418 | F23: =F22/(1+$B$10)^F14 -> 425.43261 | G23: =G22/(1+$B$10)^G14 -> 412.31817
A24: Total PV of FCF | B24: =SUM(C23:G23) -> 2196.9733
A25: Terminal Value | B25: =(G22*(1+B11))/(B10-B11) -> 12466.254
A26: PV of Terminal Value | B26: =B25/(1+$B$10)^$G$14 -> 9032.4728
A27: Enterprise Value | B27: =B24+B26 -> 11229.446
A28: Net Debt | B28: =('GT-US-BS'!K47+'GT-US-BS'!K54)-'GT-US-BS'!K11 -> 7922
A29: Equity Value | B29: =B27-B28 -> 3307.4461
A30: Implied Price Per Share | B30: =B29/B12 -> 11.484188
A31: Price Per Share as of 05/02/2025 | B31: 11.01
A32: Return | B32: =B30/B31-1 -> 0.043068823

Sheet Ratio_Analysis
A1: Ratio Analysis: | B1: DEC '20 | C1: DEC '21 | D1: DEC '22 | E1: DEC '23 | F1: DEC '24
A2: Current Ratio | B2: ='GT-US-BS'!G24/'GT-US-BS'!G52 -> 1.1006659 | C2: ='GT-US-BS'!H24/'GT-US-BS'!H52 -> 1.1087417 | D2: ='GT-US-BS'!I24/'GT-US-BS'!I52 -> 1.2135854 | E2: ='GT-US-BS'!J24/'GT-US-BS'!J52 -> 1.0703792 | F2: ='GT-US-BS'!K24/'GT-US-BS'!K52 -> 1.0402072
A3: Quick Ratio | B3: =('GT-US-BS'!G24-'GT-US-BS'!G18)/'GT-US-BS'!G52 -> 0.67900509 | C3: =('GT-US-BS'!H24-'GT-US-BS'!H18)/'GT-US-BS'!H52 -> 0.56518451 | D3: =('GT-US-BS'!I24-'GT-US-BS'!I18)/'GT-US-BS'!I52 -> 0.57338936 | E3: =('GT-US-BS'!J24-'GT-US-BS'!J18)/'GT-US-BS'!J52 -> 0.55295928 | F3: =('GT-US-BS'!K24-'GT-US-BS'!K18)/'GT-US-BS'!K52 -> 0.5499523
A4: Debt Ratio | B4: ='GT-US-BS'!G62/'GT-US-BS'!G44 -> 0.80255665 | C4: ='GT-US-BS'!H62/'GT-US-BS'!H44 -> 0.75777965 | D4: ='GT-US-BS'!I62/'GT-US-BS'!I44 -> 0.75631938 | E4: ='GT-US-BS'!J62/'GT-US-BS'!J44 -> 0.77587805 | F4: ='GT-US-BS'!K62/'GT-US-BS'!K44 -> 0.76597977
A5: Earnings Per Share | B5: ='GT-US-IS'!G54 -> -5.359 | C5: ='GT-US-IS'!H54 -> 2.9272 | D5: ='GT-US-IS'!I54 -> 0.7113 | E5: ='GT-US-IS'!J54 -> -2.4175 | F5: ='GT-US-IS'!K54 -> 0.2439
A6: Return on Assets | B6: ='GT-US-IS'!G50/AVERAGE('GT-US-BS'!F44,'GT-US-BS'!G44) -> -0.074441245 | C6: ='GT-US-IS'!H50/AVERAGE('GT-US-BS'!G44,'GT-US-BS'!H44) -> 0.040308114 | D6: ='GT-US-IS'!I50/AVERAGE('GT-US-BS'!H44,'GT-US-BS'!I44) -> 0.0092168001 | E6: ='GT-US-IS'!J50/AVERAGE('GT-US-BS'!I44,'GT-US-BS'!J44) -> -0.031308931 | F6: ='GT-US-IS'!K50/AVERAGE('GT-US-BS'!J44,'GT-US-BS'!K44) -> 0.0032905561
A7: Return on Equity | B7: ='GT-US-IS'!G51/AVERAGE('GT-US-BS'!F71,'GT-US-BS'!G71) -> -0.33759591 | C7: ='GT-US-IS'!H51/AVERAGE('GT-US-BS'!G71,'GT-US-BS'!H71) -> 0.18917915 | D7: ='GT-US-IS'!I51/AVERAGE('GT-US-BS'!H71,'GT-US-BS'!I71) -> 0.039227109 | E7: ='GT-US-IS'!J51/AVERAGE('GT-US-BS'!I71,'GT-US-BS'!J71) -> -0.13824238 | F7: ='GT-US-IS'!K51/AVERAGE('GT-US-BS'!J71,'GT-US-BS'!K71) -> 0.014855688
A8: Revenue growth | B8: ='GT-US-IS'!G10/'GT-US-IS'!F10-1 -> -0.16439471 | C8: ='GT-US-IS'!H10/'GT-US-IS'!G10-1 -> 0.41855369 | D8: ='GT-US-IS'!I10/'GT-US-IS'!H10-1 -> 0.19035359 | E8: ='GT-US-IS'!J10/'GT-US-IS'!I10-1 -> -0.035520308 | F8: ='GT-US-IS'!K10/'GT-US-IS'!J10-1 -> -0.059204625
A9: Profit Margin | B9: ='GT-US-IS'!G50/'GT-US-IS'!G10 -> -0.10177745 | C9: ='GT-US-IS'!H50/'GT-US-IS'!H10 -> 0.043712095 | D9: ='GT-US-IS'!I50/'GT-US-IS'!I10 -> 0.0097092045 | E9: ='GT-US-IS'!J50/'GT-US-IS'!J10 -> -0.034336689 | F9: ='GT-US-IS'!K50/'GT-US-IS'!K10 -> 0.0037080199

Sheet CCC
A1: Cash Conversion Cycle
A3: Line Item | B3: 2019 | C3: 2020 | D3: 2021 | E3: 2022 | F3: 2023 | G3: 2024
A5: Sales | B5: ='GT-US-IS'!F10 -> 14745 | C5: ='GT-US-IS'!G10 -> 12321 | D5: ='GT-US-IS'!H10 -> 17478 | E5: ='GT-US-IS'!I10 -> 20805 | F5: ='GT-US-IS'!J10 -> 20066 | G5: ='GT-US-IS'!K10 -> 18878
A6: COGS | B6: ='GT-US-IS'!F11 -> 11171 | C6: ='GT-US-IS'!G11 -> 9846 | D6: ='GT-US-IS'!H11 -> 13264 | E6: ='GT-US-IS'!I11 -> 16556 | F6: ='GT-US-IS'!J11 -> 16138 | G6: ='GT-US-IS'!K11 -> 14897
A7: Inventory (end of year) | B7: ='GT-US-BS'!F18 -> 2851 | C7: ='GT-US-BS'!G18 -> 2153 | D7: ='GT-US-BS'!H18 -> 3594 | E7: ='GT-US-BS'!I18 -> 4571 | F7: ='GT-US-BS'!J18 -> 3698 | G7: ='GT-US-BS'!K18 -> 3597
A8: Customer receivables (end of year) | B8: ='GT-US-BS'!F14 -> 1938 | C8: ='GT-US-BS'!G14 -> 1690 | D8: ='GT-US-BS'!H14 -> 2376 | E8: ='GT-US-BS'!I14 -> 2604 | F8: ='GT-US-BS'!J14 -> 2718 | G8: ='GT-US-BS'!K14 -> 2450
A9: Supplier payables (end of year) | B9: ='GT-US-BS'!F48 -> 2908 | C9: ='GT-US-BS'!G48 -> 2945 | D9: ='GT-US-BS'!H48 -> 4148 | E9: ='GT-US-BS'!I48 -> 4803 | F9: ='GT-US-BS'!J48 -> 4326 | G9: ='GT-US-BS'!K48 -> 4052
A10: Days in year | B10: 365 | C10: 365 | D10: =C10 -> 365 | E10: =D10 -> 365 | F10: =E10 -> 365 | G10: =F10 -> 365
A12: Sales per day | B12: =B5/B$10 -> 40.39726 | C12: =C5/C$10 -> 33.756164 | D12: =D5/D$10 -> 47.884932 | E12: =E5/E$10 -> 57 | F12: =F5/F$10 -> 54.975342 | G12: =G5/G$10 -> 51.720548
A13: COGS per day | B13: =B6/B$10 -> 30.605479 | C13: =C6/C$10 -> 26.975342 | D13: =D6/D$10 -> 36.339726 | E13: =E6/E$10 -> 45.358904 | F13: =F6/F$10 -> 44.213699 | G13: =G6/G$10 -> 40.813699
A15: Average Inventory | C15: =(C7+B7)/2 -> 2502 | D15: =(D7+C7)/2 -> 2873.5 | E15: =(E7+D7)/2 -> 4082.5 | F15: =(F7+E7)/2 -> 4134.5 | G15: =(G7+F7)/2 -> 3647.5
A16: Average customer receivables | C16: =(C8+B8)/2 -> 1814 | D16: =(D8+C8)/2 -> 2033 | E16: =(E8+D8)/2 -> 2490 | F16: =(F8+E8)/2 -> 2661 | G16: =(G8+F8)/2 -> 2584
A17: Average supplier payables | C17: =(C9+B9)/2 -> 2926.5 | D17: =(D9+C9)/2 -> 3546.5 | E17: =(E9+D9)/2 -> 4475.5 | F17: =(F9+E9)/2 -> 4564.5 | G17: =(G9+F9)/2 -> 4189
A19: Days inventory is held | C19: =C15/C13 -> 92.751371 | D19: =D15/D13 -> 79.073243 | E19: =E15/E13 -> 90.004379 | F19: =F15/F13 -> 93.511742 | G19: =G15/G13 -> 89.369504
A20: Days to collect from customers | C20: =C16/C12 -> 53.738333 | D20: =D16/D12 -> 42.455945 | E20: =E16/E12 -> 43.684211 | F20: =F16/F12 -> 48.403518 | G20: =G16/G12 -> 49.960801
A21: Days to pay suppliers | C21: =C17/C13 -> 108.48796 | D21: =D17/D13 -> 97.592921 | E21: =E17/E13 -> 98.66861 | F21: =F17/F13 -> 103.23724 | G21: =G17/G13 -> 102.63711
A23: Cash conversion cycle | C23: =C19+C20-C21 -> 38.001739 | D23: =D19+D20-D21 -> 23.936267 | E23: =E19+E20-E21 -> 35.01998 | F23: =F19+F20-F21 -> 38.678026 | G23: =G19+G20-G21 -> 36.693197

Sheet DEBT
A1: Debt Capitalization
R2: 2017 | S2: 2018 | T2: 2019 | U2: 2020 | V2: 2021 | W2: 2022 | X2: 2023 | Y2: 2024
B3: Dec '24 | C3: Dec '23 | D3: Dec '22 | E3: Dec '21 | F3: Dec '20 | G3: Dec '19 | H3: Dec '18 | I3: Dec '17 | R3: =I23 -> 5689 | S3: =H23 -> 5726 | T3: =G23 -> 5414 | U3: =F23 -> 5740 | V3: =E23 -> 7142 | W3: =D23 -> 7635 | X3: =C23 -> 7356 | Y3: =B23 -> 7521
A4: Short Term Debt | B4: 1390 | C4: 793 | D4: 623 | E4: 749 | F4: 558 | G4: 910 | H4: 653 | I4: 653
A5: Current Portion of LTD | B5: 832 | C5: 449 | D5: 228 | E5: 343 | F5: 152 | G5: 562 | H5: 243 | I5: 391
A6: ST Revolver - Unsec. | B6: 558 | C6: 344 | D6: 395 | E6: 406 | F6: 406 | G6: 348 | H6: 410 | I6: 262
A7: Short Term - Other | B7: - | C7: - | D7: - | E7: - | F7: - | G7: - | H7: - | I7: -
A8: Long Term Debt | B8: 6963 | C8: 7012 | D8: 7240 | E8: 6736 | F8: 5334 | G8: 5066 | H8: 5316 | I8: 5427
A9: Revolving Credit | B9: 1607 | C9: 1304 | D9: 1491 | E9: 867 | F9: 894 | G9: 1188 | H9: 1419 | I9: 1531
A10: Asset-Backed Facility | B10: 227 | C10: 244 | D10: 267 | E10: 279 | F10: 291 | G10: 327 | H10: 335 | I10: 224
A11: Sec. Rev. Facility | B11: 700 | C11: 385 | D11: 374 | E11: 0 | F11: 0 | G11: 0 | H11: 0 | I11: 0
A12: Unsec. Rev. Facility | B12: 680 | C12: 675 | D12: 850 | E12: 588 | F12: 603 | G12: 861 | H12: 1084 | I12: 1307
A13: Term Loans | B13: 147 | C13: 174 | D13: 235 | E13: 333 | F13: 612 | G13: 595 | H13: 619 | I13: 612
A14: Sec. 2nd Lien TL | B14: - | C14: - | D14: - | E14: - | F14: 400 | G14: 400 | H14: 400 | I14: 400
A15: Unsec. Delayed Drawdown TL | B15: 147 | C15: 174 | D15: 235 | E15: 333 | F15: 212 | G15: 195 | H15: 219 | I15: 212
A16: Notes/Bonds | B16: 5231.1 | C16: 5558.7 | D16: 5543.8 | E16: 5589 | F16: 3857 | G16: 3311 | H16: 3314 | I16: 3325
A17: Senior Unsec. | B17: 5231.1 | C17: 5558.7 | D17: 5543.8 | E17: 5589 | F17: 3857 | G17: 3311 | H17: 3314 | I17: 3325
A18: Other | B18: -22.1 | C18: -24.7 | D18: -29.8 | E18: -53 | F18: -29 | G18: -28 | H18: -36 | I18: -41
A19: Adjustments | B19: -22.1 | C19: -24.7 | D19: -29.8 | E19: -53 | F19: -29 | G19: -28 | H19: -36 | I19: -41
A20: Long Term Debt, Less Current Portion | B20: 6131 | C20: 6563 | D20: 7012 | E20: 6393 | F20: 5182 | G20: 4504 | H20: 5073 | I20: 5036
A21: Long Term Debt | B21: 6963 | C21: 7012 | D21: 7240 | E21: 6736 | F21: 5334 | G21: 5066 | H21: 5316 | I21: 5427
A22: Current Portion of LTD | B22: -832 | C22: -449 | D22: -228 | E22: -343 | F22: -152 | G22: -562 | H22: -243 | I22: -391
A23: Total Debt | B23: 7521 | C23: 7356 | D23: 7635 | E23: 7142 | F23: 5740 | G23: 5414 | H23: 5726 | I23: 5689
A24: All figures in millions of USD | Source: FactSet Debt Capital Structure
A25: Change | B25: =B23/C23-1 -> 0.022430669 | C25: =C23/D23-1 -> -0.03654224 | D25: =D23/E23-1 -> 0.069028283 | E25: =E23/F23-1 -> 0.24425087 | F25: =F23/G23-1 -> 0.060214259 | G25: =G23/H23-1 -> -0.054488299 | H25: =H23/I23-1 -> 0.0065037792
