Workbook

Sheet Exhibit 1
A1: Exhibit 1
A2: THIS BUD’S FOR WHO? THE BATTLE FOR ANHEUSER-BUSCH
A3: Anheuser-Busch Key Financials, 2004–2007
A5: A3:HA3:I38
A6: Year ended Dec. 31 (in millions, except where noted) | C6: 2004 | E6: 2005 | G6: 2006 | I6: 2007 | J6: 2008
A8: Barrels of beer sold:
A9: U.S. | C9: 103 | E9: 101.1 | G9: 102.3 | I9: 104.4
A10: International | C10: 13.8 | E10: 20.8 | G10: 22.7 | I10: 24
A11: Worldwide Anheuser-Busch Brands | C11: 116.8 | E11: 121.9 | G11: 125 | I11: 128.4
A12: Equity Partner Brands | C12: 19.3 | E12: 26.4 | G12: 31.6 | I12: 33.2
A13: Total Brands | C13: 136.1 | E13: 148.3 | G13: 156.6 | I13: 161.6
A15: Gross sales | C15: 17160 | E15: 17254 | G15: 17957.8 | I15: 18988.7
A16: Excise taxes | G16: 2240.7 | I16: 2303
A17: Net sales | C17: 14934 | E17: 15036 | G17: 15717.1 | I17: 16685.7
A18: Gross profit | C18: 5951.7 | E18: 5456.2 | G18: 5552.1 | I18: 5849.6
A19: As a percentage of net sales | C19: 0.399 | E19: 0.363 | G19: 0.353 | I19: 0.351
A20: Operating income | C20: 3361 | E20: 2621 | G20: 2719.6 | I20: 2894
A21: As a percentage of net sales | C21: 0.225 | E21: 0.174 | G21: 0.173 | I21: 0.173
A22: Equity income, net of tax | C22: 404 | E22: 498 | G22: 588.8 | I22: 662.4
A23: Net income | C23: 2119 | E23: 1744 | G23: 1965.2 | I23: 2115.3
A24: Diluted earnings per share | C24: 2.62 | E24: 2.23 | G24: 2.53 | I24: 2.79
A25: Diluted weighted average shares outstanding | C25: 808.5 | E25: 780.6 | G25: 777 | I25: 757.1
A27: Operating cash flow before the change in working capital | C27: 3121.9 | E27: 2677.5 | G27: 2520.6 | I27: 2963.1
A28: Common dividends paid | C28: 742.8 | E28: 800.8 | G28: 871.6 | I28: 932.4 | L28: 2004-2005 | M28: 2005-2006 | N28: 2006-2007 | P28: Average
A29: Per share (in dollars) | C29: 0.93 | E29: 1.03 | G29: 1.13 | I29: 1.25 | J29: =I29*(1+P29) -> 1.3795037 | L29: =E29/C29-1 -> 0.10752688 | M29: =G29/E29-1 -> 0.097087379 | N29: =I29/G29-1 -> 0.10619469 | P29: =AVERAGE(K29:N29) -> 0.10360298
A30: Earnings before interest, income taxes, depreciation
A31: and amortization (EBITDA)(1) | C31: 4997.4 | E31: 4419 | G31: 4672.5 | I31: 4989.9
A32: Return on shareholders equity | C32: 0.833 | E32: 0.612 | G32: 0.516 | I32: 0.597
A33: Return on capital employed(2) | C33: 0.184 | E33: 0.147 | G33: 0.156 | I33: 0.166
A35: Total assets | C35: 16173.4 | E35: 16555 | G35: 16377.2 | I35: 17155
A36: Debt | C36: 8278.6 | E36: 7972.1 | G36: 7653.5 | I36: 9140.3
A37: Capital expenditures | C37: 1089.6 | E37: 1136.7 | G37: 812.5 | I37: 870
A38: Depreciation and amortization | C38: 932.7 | E38: 979 | G38: 988.7 | I38: 996.2
A39: Number of full-time employees | C39: 31435 | E39: 31485 | G39: 30183 | I39: 30849
A40: Number of registered common shareholders | C40: 54654 | E40: 53573 | G40: 51888 | I40: 49732
A41: Closing stock price | C41: 50.73 | E41: 42.96 | G41: 49.2 | I41: 52.34
A43: Income before Income taxes | C43: 2812 | E43: 2057 | G43: 2277 | I43: 2423
A45: (1) EBITDA is calculated as pretax income plus depreciation and amortization expense, plus net interest cost (interest expense less capitalized interest), plus equity income on a pretax basis (equity income divided by the reciprocal of the effective tax rate).
A48: (2) Return on capital employed is computed as net income before after-tax interest expense divided by average net investment. Net investment is defined as total assets less nondebt current liabilities.
A51: Data source: Anheuser-Busch annual reports, 2006–2007.

Sheet Exhibit 2
A1: Exhibit 2
A2: THIS BUD’S FOR WHO? THE BATTLE FOR ANHEUSER-BUSCH
A3: Anheuser-Busch Business Segments, 2007
C6: U.S. | D6: International | G6: Corporate & | R6: Total | S6: U.S. | T6: Int'l
A7: 2007 | C7: Beer | D7: Beer | E7: Packaging | F7: Entertainment | G7: Eliminations | H7: Consolidated | R7: Beer | S7: share | T7: share
A9: Income Statement Information
A10: Gross sales | C10: 14158.7 | D10: 1351.7 | E10: 2632.8 | F10: 1272.7 | G10: -427.2 | H10: 18988.7 | J10: 0.7456382 | K10: 0.071184441 | L10: 0.13865088 | M10: 0.067024072 | N10: -0.022497591 | O10: 1 | R10: 15510.4 | S10: 0.91285202 | T10: 0.087147978
A11: Net sales - intersegment | C11: 3.2 | D11: 0.6 | E11: 931.9 | F11: — | G11: -935.7
A12: Net sales - external | C12: 12106.1 | D12: 1097.5 | E12: 1700.9 | F12: 1272.7 | G12: 508.5 | H12: 16685.7 | J12: 0.72553744 | K12: 0.065774885 | L12: 0.10193759 | M12: 0.076274894 | N12: 0.030475197 | O12: 1
A13: Depreciation and amortization | C13: 749 | D13: 49.8 | E13: 68.9 | F13: 103 | G13: 25.5 | H13: 996.2 | J13: 0.75185706 | K13: 0.049989962 | L13: 0.069162819 | M13: 0.10339289 | N13: 0.02559727 | O13: 1
A14: Income before income taxes | C14: 2784 | D14: 93.3 | E14: 175.8 | F14: 262.7 | G14: -893.1 | H14: 2422.7 | J14: 1.1491311 | K14: 0.038510752 | L14: 0.072563669 | M14: 0.10843274 | N14: -0.3686383 | O14: 1
A15: Equity income, net of tax | C15: 2.3 | D15: 660.1 | E15: — | F15: — | G15: — | H15: 662.4 | J15: 0.0034722222 | K15: 0.99652778 | O15: 1
A16: Net income | C16: 1728.4 | D16: 717.9 | E16: 109 | F16: 162.9 | G16: -602.9 | H16: 2115.3 | J16: 0.8170945 | K16: 0.33938448 | L16: 0.051529334 | M16: 0.077010353 | N16: -0.28501867 | O16: 1 | R16: 2446.3 | S16: 0.7065364 | T16: 0.2934636
A18: Balance Sheet Information
A19: Total assets | C19: 8142 | D19: 5880.8 | E19: 772.6 | F19: 1548.3 | G19: 811.3 | H19: 17155 | J19: 0.47461382 | K19: 0.34280385 | L19: 0.045036433 | M19: 0.09025357 | N19: 0.047292335 | O19: 1 | R19: 14022.8 | S19: 0.58062584 | T19: 0.41937416
A20: Equity method investments | C20: 93.9 | D20: 3925.6 | E20: — | F20: — | G20: — | H20: 4019.5 | J20: 0.023361115 | K20: 0.97663889 | O20: 1
A21: Goodwill | C21: 21.2 | D21: 1343.3 | E21: 21.9 | F21: 288.3 | G21: — | H21: 1674.7 | J21: 0.012658984 | K21: 0.80211381 | L21: 0.013076969 | M21: 0.17215024 | O21: 1
A22: Foreign-located fixed assets | C22: 4.5 | D22: 544.4 | H22: 548.9 | J22: 0.0081982146 | K22: 0.99180179 | O22: 1
A23: Capital expenditures | C23: 554.4 | D23: 59.2 | E23: 72.4 | F23: 169.4 | G23: 14.6 | H23: 870 | J23: 0.63724138 | K23: 0.068045977 | L23: 0.083218391 | M23: 0.19471264 | N23: 0.016781609 | O23: 1
A25: Data source: Anheuser-Busch annual report, 2007, 63. | J25: 1.7389708 | K25: 0.22984968 | L25: 3.4077142 | M25: 0.82199832 | N25: -0.52656231 | O25: 1.1068901 | P25: Sales / TA
J26: 0.21228199 | K26: 0.12207523 | L26: 0.14108206 | M26: 0.10521217 | N26: -0.74312831 | O26: 0.12330516 | P26: Net Y / TA

Sheet Exhibit 2 (cont.)
A1: Exhibit 2 (continued)
A2: THIS BUD’S FOR WHO? THE BATTLE FOR ANHEUSER-BUSCH
A3: Selected Financial Information for Anheuser-Busch, 2007–2009
C6: 2007A | E6: 2008E | G6: 2009P
A8: Barrels of Beer (millions)
A10: Domestic | C10: 104.4 | E10: 106.488 | G10: 108.61776
A11: International | C11: 24 | E11: 25.2 | G11: 26.712
A12: Total Barrels | C12: 128.4 | E12: 131.688 | G12: 135.32976
A14: Sales (millions)
A16: U.S. ($) | C16: 15191 | E16: 16589 | G16: 17418
A17: International (euros) | C17: 2601.1918 | E17: 2706.1017 | G17: 2815.2428
A19: Exchange rate as of year end | C19: 1.32 | E19: 1.32 | G19: 1.32
A20: Excise Tax | C20: 2303 | E20: 2392.5762 | G20: 2512.205
A21: Sales in U.S. dollars
A23: U.S. | C23: 14366.4 | E23: 14366.4 | G23: 14366.4
A24: International | C24: 3591.6 | E24: 3591.6 | G24: 3591.6
A26: Cash Flow in Dollars
A28: Total Sales | C28: 17958 | E28: 17958 | G28: 17958
A30: Cost of Goods Sold ($) | C30: 10836.6 | E30: 11334.431 | G30: 11569.541
A31: Marketing, General and Admin ($) | C31: 2981.7 | E31: 3158.2006 | G31: 3316.1106
A33: Depreciation | C33: 996 | E33: 996.90675 | G33: 1046.7521
A35: Increase in Net working Capital ($) | C35: -24 | E35: 40 | G35: 50
A36: Capital Expenditures | C36: 813 | E36: 870 | G36: 965
A37: Free Cash Flow | C37: #REF! | E37: #REF! | G37: #REF!
A39: Terminal Value
A40: Present Value
A44: Note: Figures above do not provide for income taxes or capital expenditures. Sales are expressed in dollars and euros, respectively.
A46: Data sources: Anheuser-Busch annual report, 2007; and case writer estimates.

Sheet Exhibit 3
A1: Exhibit 3
A2: THIS BUD’S FOR WHO? THE BATTLE FOR ANHEUSER-BUSCH
A3: Anheuser-Busch Adjusted Stock Price, 1998–2008
A5: PERMNO | B5: date | C5: PRC | D5: Stock Price
A6: 59184 | B6: 35797 | C6: 44.375 | D6: 22.1875
A7: 59184 | B7: 35800 | C7: 43.5 | D7: 21.75
A8: 59184 | B8: 35801 | C8: 43.5625 | D8: 21.78125 | F8: AB Stock Price Prior to Merger with InBev (Prices prior to 9/18/2000 adjusted due to stock spilt)
A9: 59184 | B9: 35802 | C9: 43.4375 | D9: 21.71875
A10: 59184 | B10: 35803 | C10: 43.75 | D10: 21.875
A11: 59184 | B11: 35804 | C11: 43.9375 | D11: 21.96875
A12: 59184 | B12: 35807 | C12: 44.9375 | D12: 22.46875
A13: 59184 | B13: 35808 | C13: 43.8125 | D13: 21.90625
A14: 59184 | B14: 35809 | C14: 43.4375 | D14: 21.71875
A15: 59184 | B15: 35810 | C15: 44.0625 | D15: 22.03125
A16: 59184 | B16: 35811 | C16: 44.5 | D16: 22.25
A17: 59184 | B17: 35815 | C17: 44.875 | D17: 22.4375
A18: 59184 | B18: 35816 | C18: 44.0625 | D18: 22.03125
A19: 59184 | B19: 35817 | C19: 45.375 | D19: 22.6875
A20: 59184 | B20: 35818 | C20: 44.75 | D20: 22.375
... A30: 59184 | B30: 35832 | C30: 45.3125 | D30: 22.65625
A31: 59184 | B31: 35835 | C31: 46.3125 | D31: 23.15625 | F31: Data sources: ChicagoBooth CRSP Historical Indexes, http://www.crsp.com/products/research-products/crsp-historical-indexes (accessed Sep. 5, 2014).
A32: 59184 | B32: 35836 | C32: 46.5 | D32: 23.25
A33: 59184 | B33: 35837 | C33: 46.5 | D33: 23.25
A34: 59184 | B34: 35838 | C34: 46.5625 | D34: 23.28125
A35: 59184 | B35: 35839 | C35: 46.4375 | D35: 23.21875
A36: 59184 | B36: 35843 | C36: 46.625 | D36: 23.3125
A37: 59184 | B37: 35844 | C37: 47.4375 | D37: 23.71875
A38: 59184 | B38: 35845 | C38: 47.5 | D38: 23.75
A39: 59184 | B39: 35846 | C39: 46.875 | D39: 23.4375
A40: 59184 | B40: 35849 | C40: 46.4375 | D40: 23.21875
A41: 59184 | B41: 35850 | C41: 46.3125 | D41: 23.15625
A42: 59184 | B42: 35851 | C42: 46.5 | D42: 23.25
A43: 59184 | B43: 35852 | C43: 46.9375 | D43: 23.46875
... A2732: 59184 | B2732: 39755 | C2732: 63.54 | D2732: 63.54
A2733: 59184 | B2733: 39756 | C2733: 64.6 | D2733: 64.6 | N2733: 1.519509
A2734: 59184 | B2734: 39757 | C2734: 64 | D2734: 64
A2735: 59184 | B2735: 39758 | C2735: 64.58 | D2735: 64.58
A2736: 59184 | B2736: 39759 | C2736: 65.69 | D2736: 65.69
A2737: 59184 | B2737: 39762 | C2737: 66.59 | D2737: 66.59
A2738: 59184 | B2738: 39763 | C2738: 66.84 | D2738: 66.84
...

Sheet Exhibit 4
A2: Exhibit 4
A3: THIS BUD’S FOR WHO? THE BATTLE FOR ANHEUSER-BUSCH
A4: Operating and Financial Projections Associated with Operating Efficiencies
A7: Year ended Dec. 31 (in millions, except where noted) | C7: 2007A | D7: 2008E | E7: 2009P | F7: 2010P | G7: 2011P | H7: 2012P
A9: Barrels of beer sold: (000)
A10: U.S. | C10: 104.4 | D10: 106.488 | E10: 108.61776 | F10: 110.79012 | G10: 113.00592 | H10: 115.26604
A11: International | C11: 24 | D11: 25.2 | E11: 26.712 | F11: 28.58184 | G11: 30.582569 | H11: 32.723349
A12: Worldwide Anheuser-Busch Brands | C12: 128.4 | D12: 131.688 | E12: 135.32976 | F12: 139.37196 | G12: 143.58849 | H12: 147.98938
A13: Equity Partner Brands | C13: 33.2 | D13: 34.86 | E13: 36.603 | F13: 38.43315 | G13: 40.354808 | H13: 42.372548
A14: Total Brands | C14: 161.6 | D14: 166.548 | E14: 171.93276 | F14: 177.80511 | G14: 183.94329 | H14: 190.36193
A16: Gross sales | C16: 18988.7 | D16: 19938.135 | E16: 20935.042 | F16: 22191.144 | G16: 23744.524 | H16: 25406.641
A17: Excise taxes | C17: 2303 | D17: 2392.5762 | E17: 2512.205 | F17: 2662.9373 | G17: 2849.3429 | H17: 3048.7969
A18: Net sales | C18: 16685.7 | D18: 17545.559 | E18: 18422.837 | F18: 19528.207 | G18: 20895.181 | H18: 22357.844
A19: Cost of goods sold | C19: 10836.6 | D19: 11334.431 | E19: 11569.541 | F19: 12166.073 | G19: 12955.012 | H19: 13861.863
A20: As a percentage of net sales | C20: 0.64945432 | D20: 0.646 | E20: 0.628 | F20: 0.623 | G20: 0.62 | H20: 0.62
A21: Gross profit | C21: 5849.4 | D21: 6211.1278 | E21: 6853.2953 | F21: 7362.134 | G21: 7940.1689 | H21: 8495.9808
A22: As a percentage of net sales | C22: 0.35056366 | D22: 0.354 | E22: 0.372 | F22: 0.377 | G22: 0.38 | H22: 0.38
... A38: Diluted weighted average shares outstanding | C38: 757.1 | D38: 725 | E38: 725 | F38: 725 | G38: 725 | H38: 725
A40: (1) Pretax equity income is calculated as equity income divided by the reciprocal of the tax rate. This income is related to AB’s investment in Grupo Modelo and should be added back to AB’s stand-alone free cash flow for valuation purposes.
A43: Note: Analysts estimated WACC at 8.4% (William Pecoriello and Brett Cooper, “Anheuser-Busech Cos,” Morgan Stanley, June 27, 2008, 3.)
A45: Data sources: Anheuser-Busch annual reports, 2006–2007, and case writer estimates.

Sheet Exhibit 5
A2: THIS BUD’S FOR WHO? THE BATTLE FOR ANHEUSER-BUSCH
A3: Selected Exchange Rates, 2003–2008
A6: Quarterly Period | C6: USD/EUR | E6: USD/MXN | G6: USD/CNY
A7: Jul. 1, 2003–Sep. 30, 2003 | C7: 0.8878 | E7: 10.703 | G7: 8.2672
A8: Oct. 1, 2003–Dec. 31, 2003 | C8: 0.8404 | E8: 11.1744 | G8: 8.2669
A9: Jan. 1, 2004–Mar. 31, 2004 | C9: 0.8006 | E9: 10.9792 | G9: 8.2671
A10: Apr. 1, 2004–Jun. 30, 2004 | C10: 0.8296 | E10: 11.3687 | G10: 8.2666
A11: Jul. 1, 2004–Sep. 30, 2004 | C11: 0.8178 | E11: 11.4234 | G11: 8.2655
A12: Oct. 1, 2004–Dec. 31, 2004 | C12: 0.7716 | E12: 11.295 | G12: 8.2663
A13: Jan. 1, 2005–Mar. 31, 2005 | C13: 0.7621 | E13: 11.1619 | G13: 8.2665
A14: Apr. 1, 2005–Jun. 30, 2005 | C14: 0.7938 | E14: 10.9575 | G14: 8.2665
A15: Jul. 1, 2005–Sep. 30, 2005 | C15: 0.8195 | E15: 10.7057 | G15: 8.1301
A16: Oct. 1, 2005–Dec. 31, 2005 | C16: 0.8407 | E16: 10.7031 | G16: 8.0746
A17: Jan. 1, 2006–Mar. 31, 2006 | C17: 0.8316 | E17: 10.5797 | G17: 8.0469
A18: Apr. 1, 2006–Jun. 30, 2006 | C18: 0.7962 | E18: 11.1588 | G18: 8.0028
... A25: Jan. 1, 2008–Mar. 31, 2008 | C25: 0.6681 | E25: 10.8021 | G25: 7.1554
A27: Data source: OANDA Historical Exchange Rates, http://www.oanda.com/currency/historical-rates (accessed Jul. 8, 2013).

Sheet Exhibit 6
A1: Exhibit 6
A2: THIS BUD’S FOR WHO? THE BATTLE FOR ANHEUSER-BUSCH
A3: Selected Capital Market Information, December 2007
B5: Euro Zone (euros)* | C5: USD($)
A6: Domestic government bonds (long term) | B6: 0.0438 | C6: 0.0443
A7: 3-month treasury bill rate | C7: 0.0337
A9: Spot rate of euro, end of 2007 | C9: 1.47
A11: Inflation rates: yearly, 2002–2007
A13: 2002 | C13: 0.016
A14: 2003 | C14: 0.023
A15: 2004 | C15: 0.027
A16: 2005 | C16: 0.034
A17: 2006 | C17: 0.032
A18: 2007 | C18: 0.028
A20: * euro-area 10-year government benchmark bond yield
A22: Data sources: U.S. Treasury Department, European Central Bank, and U.S. Inflation Calculator.

Sheet Question 1
B2: 1. Strategically, the deal makes sense. Beer is a scale business, and the industry was consolidating. The case highlighted two biggest advantages of being large: the economies of scale (lower production costs from larger production) and more efficient spending on marketing and advertising.
B4: To answer why it makes sense:
B5: InBev wanted the US market. The United States was a “conspicuous gap” for InBev. Anheuser-Busch was the ideal candidate to enter the US Market.
B6: Despite the global trends, Anheuser-Busch was conservative in its expansion, focused more on licensing and taking minority stakes.
B7: Staying local made Anheuser-Busch less competitive globally, resulting in being displaced in global rankings by competitors with a more aggressive expansion strategy.
B8: Despite U.S. Market dominance, Anheuser-Busch’s stock price had been stagnant for some time. This made them a strategically vulnerable target.
B10: As for the value creation, we saw two different ways:
B11: 1.) Operating synergies: InBev was displayed as a company that paid attention to cost-cutting, which ultimately led to value realization. The case mentioned the 2006 joint venture gave InBev an inside look at Anheuser-Busch and highlighted “room for improvement through strategic diversification and more efficient operations.” Anheuser-Busch already benefited from scale (SG&A 18% of sales), but InBev believed there was still “organizational slack.” A bigger combined volume would allow better economies of scale and capacity to be utilized. Anheuser-Busch’s management itself pointed out the capacity to save from reducing CAPEX (from 5% to 3%).
B12: 2.) Corporate strategy synergies: because of Anheuser-Busch’s branding culture, it owns huge non-core assets. InBev intended to sell these assets to fund the transaction and improve focus on beer production. By doing so, there was potential in monetizing Anheuser-Busch’s 50.2% stake in Modelo.

Sheet Question 2
A1: Years | B1: 1 | C1: 2 | D1: 3 | E1: 4 | F1: 5
A2: Net Sales | B2: ='Exhibit 4'!D18 -> 17545.559 | C2: ='Exhibit 4'!E18 -> 18422.837 | D2: ='Exhibit 4'!F18 -> 19528.207 | E2: ='Exhibit 4'!G18 -> 20895.181 | F2: ='Exhibit 4'!H18 -> 22357.844
A3: EBIT | B3: ='Exhibit 4'!D25 -> 3052.9272 | C3: ='Exhibit 4'!E25 -> 3537.1847 | D3: ='Exhibit 4'!F25 -> 3847.0568 | E3: ='Exhibit 4'!G25 -> 4179.0363 | F3: ='Exhibit 4'!H25 -> 4471.5688
A4: Tax Rate | B4: ='Exhibit 4'!D29 -> 0.395 | C4: ='Exhibit 4'!E29 -> 0.395 | D4: ='Exhibit 4'!F29 -> 0.395 | E4: ='Exhibit 4'!G29 -> 0.395 | F4: ='Exhibit 4'!H29 -> 0.395
A5: EBIT(1-T) | B5: =B3*(1-B4) -> 1847.021 | C5: =C3*(1-C4) -> 2139.9967 | D5: =D3*(1-D4) -> 2327.4693 | E5: =E3*(1-E4) -> 2528.317 | F5: =F3*(1-F4) -> 2705.2991
A6: Equity income, net of tax | B6: ='Exhibit 4'!D31 -> 701.82235 | C6: ='Exhibit 4'!E31 -> 736.91347 | D6: ='Exhibit 4'!F31 -> 781.12828 | E6: ='Exhibit 4'!G31 -> 835.80726 | F6: ='Exhibit 4'!H31 -> 894.31377
A7: NOPAT | B7: =B5+B6 -> 2548.8433 | C7: =C5+C6 -> 2876.9102 | D7: =D5+D6 -> 3108.5976 | E7: =E5+E6 -> 3364.1242 | F7: =F5+F6 -> 3599.6129
A8: Depreciation | B8: ='Exhibit 2 (cont.)'!E33 -> 996.90675 | C8: ='Exhibit 2 (cont.)'!G33 -> 1046.7521 | D8: =D2*$G$8 -> 1109.5572 | E8: =E2*$G$8 -> 1187.2262 | F8: =F2*$G$8 -> 1270.3321 | G8: =C8/C2 -> 0.056818182 | H8: <-- Used this to determine Depreciation as a % of Net Sales
A9: CAPEX (% of sales Assumption) | B9: =B2*$G$9 -> 614.09456 | C9: =C2*$G$9 -> 644.79929 | D9: =D2*$G$9 -> 683.48724 | E9: =E2*$G$9 -> 731.33135 | F9: =F2*$G$9 -> 782.52454 | G9: 0.035 | H9: <-- According to the case CAPEX was just over 5%, but the management expected it to fall into 3%-4% range. Using 3.5% as base case
A10: Change in NWC | B10: ='Exhibit 2 (cont.)'!E35 -> 40 | C10: ='Exhibit 2 (cont.)'!G35 -> 50 | D10: =D2*$G$10 -> 53 | E10: =E2*$G$10 -> 56.71 | F10: =F2*$G$10 -> 60.6797 | G10: =I10 -> 0.0027140229 | H10: =B10/B2 -> 0.0022797792 | I10: =C10/C2 -> 0.0027140229 | J10: <-- change in NWC as a % of Net Sales. Using 0.27 as base case
A11: FCFF | B11: =B7+B8-B9-B10 -> 2891.6555 | C11: =C7+C8-C9-C10 -> 3228.863 | D11: =D7+D8-D9-D10 -> 3481.6676 | E11: =E7+E8-E9-E10 -> 3763.3091 | F11: =F7+F8-F9-F10 -> 4026.7407
A12: Present Value of FCFF | B12: =B11/(1+$G$12)^B1 -> 2667.838 | C12: =C11/(1+$G$12)^C1 -> 2748.3713 | D12: =D11/(1+$G$12)^D1 -> 2734.1731 | E12: =E11/(1+$G$12)^E1 -> 2726.6003 | F12: =F11/(1+$G$12)^F1 -> 2691.6473 | G12: =K27 -> 0.083894724 | H12: <-- using WACC to discount the CF
A13: Total PV of FCFF | B13: =SUM(B12:F12) -> 13568.63
A14: Terminal Value | B14: =(F11*(1+G14))/(G12-G14) -> 64281.92 | G14: 0.02 | H14: <-- mature beer business growth
A15: PV of TV | B15: =B14/(1+G12)^F1 -> 42968.81
A16: Enterprise Value | B16: =B13+B15 -> 56537.44
A17: Equity Value | B17: =B16-'Exhibit 1'!I36 -> 47397.14 | G17: EV-Debt-Cash | H17: Since cash is not given, assumed 0. Used Debt from 2007
A18: Price per Share | B18: =B17/G18 -> 65.375366 | G18: ='Exhibit 4'!H38 -> 725
J22: Equity | K22: =('Exhibit 3'!D2519*'Exhibit 4'!C38) -> 39626.614
A23: Year ended Dec. 31 (in millions, except where noted) | B23: 2007A | C23: 2008E | D23: 2009P | E23: 2010P | F23: 2011P | G23: 2012P | J23: Debt | K23: ='Exhibit 1'!I36 -> 9140.3
A24: Net interest expense | B24: 471.3 | C24: 500 | D24: 500 | E24: 500 | F24: 500 | G24: 500 | J24: T-Bill | K24: ='Exhibit 6'!C7 -> 0.0337
A25: Tax rate | B25: 0.40029719 | C25: 0.395 | D25: 0.395 | E25: 0.395 | F25: 0.395 | G25: 0.395 | J25: Cost of Equity (Dividend Discount Model) | K25: =('Exhibit 1'!J29/'Exhibit 3'!D2519)+(('Exhibit 1'!I28/'Exhibit 1'!G28)-1) -> 0.096113356
J26: Cost of Debt | K26: =B24/'Exhibit 1'!I36 -> 0.051562859
J27: WACC | K27: =(K22/(K23+K22)*K25)+(K23/(K23+K22)*K26*(1-B25)) -> 0.083894724 | L27: --> For the WACC, we found that doing the Dividend Discount Model would work best for the Cost of Equity portion, given there was no beta. How we did so was by predicting the 2008 dividend per share with the 2007 dividend per share and multiplying it by the previous 3 year (2005-2007) average growth of about 10.36%, and dividing it by the December 31, 2007 share price. Then, we added the 2006-2007 annual growth rate of the common dividends paid. Therefore, getting us a WACC of roughly 8.39%.

Sheet Question 3
A1: Assumptions:
A2: Additional Revenue in EUR | B2: =3000 -> 3000
A3: Sport Rate at the end of 2007 | B3: ='Exhibit 6'!C9 -> 1.47
A4: WACC | B4: ='Question 2'!G12 -> 0.083894724
A5: Revenue growth | B5: =6% -> 0.06
A6: Operating Income As a percentage of net sales | B6: ='Exhibit 4'!D26 -> 0.174
A7: Tax Rate | B7: ='Question 2'!B4 -> 0.395
A8: Base Equity Value | B8: ='Question 2'!B17 -> 47397.14
A9: # of shares | B9: ='Question 2'!G18 -> 725
A12: EUR-->USD | B12: =B2*B3 -> 4410
A13: EBIT | B13: =B12*B6 -> 767.34
A14: After Tax CF in 2008 | B14: =B13*(1-B7) -> 464.2407
A15: PV of growing perpetuity | B15: =B14/(B4-B5) -> 19428.586 | C15: <-- use Cost of Equity
A16: Base Equity Value | B16: =B8+B15 -> 66825.727
A17: New Price per share | B17: =B16/B9 -> 92.173416

Sheet Question 4
A1: Inputs
A2: WACC | B2: ='Question 2'!K27 -> 0.083894724
A3: Terminal Growth Rate | B3: ='Question 2'!G14 -> 0.02
A4: Tax Rate | B4: ='Question 3'!B7 -> 0.395 | K4: Sensitivity Analysis
A5: CAPEX %-of Net Sales | B5: 0.035 | L5: Growth Rate
A6: Shares Outstanding | B6: ='Question 3'!B9 -> 725 | K6: =B31 -> 65.375366 | L6: 0.01 | M6: 0.015 | N6: 0.02 | O6: 0.025 | P6: 0.03 | R6: The growth rate can signal a firm's health and its ability to grow with the market's conditions. With the case's specifics, the a low growth rate can signal low exopectancy of Anheuser-Busch t grow into international markets and more into the US market. The terminal value also increases dramatically as the growth rate approaches the WACC, or discount rate, because if the growth is close to discount rate, the company is generating returns that cover the financing of the firm. There is also synergy growth that is represented within the growth rate that needs to be accounted for under the valuation of acquiring a firm.
A7: Net Debt | B7: ='Exhibit 1'!I36 -> 9140.3 | J7: WACC | K7: 0.074 | L7: 67.970887 | M7: 73.498486 | N7: 80.049715 | O7: 87.937929 | P7: 97.61892
A8: FX | B8: ='Question 3'!B3 -> 1.47 | K8: 0.079 | L8: 61.952404 | M8: 66.5919 | N8: 72.017751 | O8: 78.44839 | P8: 86.191404 | R8: Another key factor is the WACC, which is a key factor affecting the valuation of Anheuser-Busch because it is not only the discount rate, but the minimum required return in which investors are expecting. Therefore, a lower WACC will increase the valuation with the higher discount, and opposite for a higher WACC. The WACC also exemplifies the breakeven discount rate where InBev may have set their $65/share offer.
A9: Synergy in EUR | B9: ='Question 3'!B2 -> 3000 | K9: 0.084 | L9: 56.75019 | M9: 60.689205 | N9: 65.243692 | O9: 70.570126 | P9: 76.882937
A10: Synergy Growth rate | B10: ='Question 3'!B5 -> 0.06 | K10: 0.089 | L10: 52.209192 | M10: 55.586847 | N10: 59.454018 | O10: 63.925434 | P10: 69.154717
A11: Incremental EBIT margin | B11: ='Question 3'!B6 -> 0.174 | K11: 0.094 | L11: 48.211277 | M11: 51.132805 | N11: 54.449133 | O11: 58.246089 | P11: 62.63632
A12: Reinvestment Rate on Synergy | B12: 0
B14: 1 | C14: 2 | D14: 3 | E14: 4 | F14: 5
A15: Net Sales | B15: ='Question 2'!B2 -> 17545.559 | C15: ='Question 2'!C2 -> 18422.837 | D15: ='Question 2'!D2 -> 19528.207 | E15: ='Question 2'!E2 -> 20895.181 | F15: ='Question 2'!F2 -> 22357.844 | J15: Sensitivity Analysis
A16: EBIT | B16: ='Question 2'!B3 -> 3052.9272 | C16: ='Question 2'!C3 -> 3537.1847 | D16: ='Question 2'!D3 -> 3847.0568 | E16: ='Question 2'!E3 -> 4179.0363 | F16: ='Question 2'!F3 -> 4471.5688 | L16: WACC
A17: EBIT after tax = EBIT * (1 - Tax rate) | B17: =B16*(1-$B$4) -> 1847.021 | C17: =C16*(1-$B$4) -> 2139.9967 | D17: =D16*(1-$B$4) -> 2327.4693 | E17: =E16*(1-$B$4) -> 2528.317 | F17: =F16*(1-$B$4) -> 2705.2991 | K17: =F43 -> 71.907425 | L17: =M17-0.5% -> 0.073894724 | M17: =N17-0.5% -> 0.078894724 | N17: =B2 -> 0.083894724 | O17: =N17+0.5% -> 0.088894724 | P17: =O17+0.5% -> 0.093894724 | R17: Key factors affecting the price InBev should pay is the average EV/EBITDA Multiple from comparable acquisitions within the brewing sector. We determined the base multiple of 11.9X because Heineken had acquired a mature asset for a multiple of 11.9X, Anheuser-Busch is definetley an above-average food and beverage company of 11.0X, and Anheuser-Busch is not strong in the international markets. Therefore, Anheuser-Busch cannot be a 14X valuation, making it more towards the 11.9X Heineken has done. This multiple seriusly affects the valuation of Anheuser-Busch because the enterprise value is reliant on the multiple as a comparison to its competition and base it off Anheuser-Busch's current prospectives.
A18: Equity income (net of tax) | B18: ='Question 2'!B6 -> 701.82235 | C18: ='Question 2'!C6 -> 736.91347 | D18: ='Question 2'!D6 -> 781.12828 | E18: ='Question 2'!E6 -> 835.80726 | F18: ='Question 2'!F6 -> 894.31377 | J18: EV/EBITDA Multiple | K18: =K19-0.5 -> 10.9 | L18: 68.989062 | M18: 70.617789 | N18: 70.617789 | O18: 68.989062 | P18: 65.864784
A19: NOPAT = EBIT after tax + Equity income | B19: =B17+B18 -> 2548.8433 | C19: =C17+C18 -> 2876.9102 | D19: =D17+D18 -> 3108.5976 | E19: =E17+E18 -> 3364.1242 | F19: =F17+F18 -> 3599.6129 | K19: =K20-0.5 -> 11.4 | L19: 65.824426 | M19: 67.378441 | N19: 67.378441 | O19: 65.824426 | P19: 62.843464 | R19: Another key factor is the WACC, which is a key factor affecting the valuation of Anheuser-Busch because it is not only the discount rate, but the minimum required return in which investors are expecting. Therefore, a lower WACC will increase the valuation with the higher discount, and opposite for a higher WACC. The WACC also exemplifies the breakeven discount rate where InBev may have set their $65/share offer.
A20: Depreciation | B20: ='Question 2'!B8 -> 996.90675 | C20: ='Question 2'!C8 -> 1046.7521 | D20: ='Question 2'!D8 -> 1109.5572 | E20: ='Question 2'!E8 -> 1187.2262 | F20: ='Question 2'!F8 -> 1270.3321 | K20: =F41 -> 11.9 | L20: 65.824426 | M20: 67.378441 | N20: 67.378441 | O20: 65.824426 | P20: 62.843464
A21: Capex | B21: =B15*$B$5 -> 614.09456 | C21: =C15*$B$5 -> 644.79929 | D21: =D15*$B$5 -> 683.48724 | E21: =E15*$B$5 -> 731.33135 | F21: =F15*$B$5 -> 782.52454 | K21: =K20+0.5 -> 12.4 | L21: 68.989062 | M21: 70.617789 | N21: 70.617789 | O21: 68.989062 | P21: 65.864784
A22: Change in NWC | B22: ='Question 2'!B10 -> 40 | C22: ='Question 2'!C10 -> 50 | D22: ='Question 2'!D10 -> 53 | E22: ='Question 2'!E10 -> 56.71 | F22: ='Question 2'!F10 -> 60.6797 | K22: =K21+0.5 -> 12.9 | L22: 75.318334 | M22: 77.096485 | N22: 77.096485 | O22: 75.318334 | P22: 71.907425
A23: FCFF = NOPAT + Depreciation - Capex - ΔNWC | B23: =B19+B20-B21-B22 -> 2891.6555 | C23: =C19+C20-C21-C22 -> 3228.863 | D23: =D19+D20-D21-D22 -> 3481.6676 | E23: =E19+E20-E21-E22 -> 3763.3091 | F23: =F19+F20-F21-F22 -> 4026.7407
A24: Discount Factor | B24: =1/((1+$B$2)^B14) -> 0.92259883 | C24: =1/((1+$B$2)^C14) -> 0.85118859 | D24: =1/((1+$B$2)^D14) -> 0.7853056 | E24: =1/((1+$B$2)^E14) -> 0.72452202 | F24: =1/((1+$B$2)^F14) -> 0.66844317
A25: PV of FCFF | B25: =B23*B24 -> 2667.838 | C25: =C23*C24 -> 2748.3713 | D25: =D23*D24 -> 2734.1731 | E25: =E23*E24 -> 2726.6003 | F25: =F23*F24 -> 2691.6473
A26: Total PV of FCFF | B26: =SUM(B25:F25) -> 13568.63
A27: Terminal Value | B27: =(F25*(1+B3))/(B2-B3) -> 42968.81
A28: PV of TV | B28: =(F23*(1+B3))/(B2-B3) -> 64281.92
A29: Enterprise Value | B29: =B27+B26 -> 56537.44
A30: Equity Value | B30: =B29-'Exhibit 1'!I36 -> 47397.14
A31: Price per Share | B31: =B30/B6 -> 65.375366
B35: Year | C35: 0 | D35: 1 | E35: 2 | F35: 3 | G35: 4 | H35: 5
B36: EBITDA | C36: ='Question 4'!C73+'Question 4'!C66+'Question 4'!C69+'Question 4'!C72 -> 4660.9471 | D36: ='Question 4'!D73+'Question 4'!D66+'Question 4'!D69+'Question 4'!D72 -> 4914.7865 | E36: ='Question 4'!E73+'Question 4'!E66+'Question 4'!E69+'Question 4'!E72 -> 5492.1369 | F36: ='Question 4'!F73+'Question 4'!F66+'Question 4'!F69+'Question 4'!F72 -> 5919.3062 | G36: ='Question 4'!G73+'Question 4'!G66+'Question 4'!G69+'Question 4'!G72 -> 6396.3431 | H36: ='Question 4'!H73+'Question 4'!H66+'Question 4'!H69+'Question 4'!H72 -> 6844.0872 | I36: --> forecasted EBTIDA using bottom-up approach
B37: PV(EBITDA) | C37: =C36/(1+'Question 4'!$D$71)^C35 -> 4660.9471 | D37: =D36/(1+$B$2)^D35 -> 4534.3763 | E37: =E36/(1+$B$2)^E35 -> 4674.8443 | F37: =F36/(1+$B$2)^F35 -> 4648.4643 | G37: =G36/(1+$B$2)^G35 -> 4634.2915 | H37: =H36/(1+$B$2)^H35 -> 4574.8833 | I37: --> present values of the forecasted EBTIDA
D40: Average Comps | E40: High-Comps | F40: Heineken Comp
C41: EV/EBITDA Multiples | D41: 11 | E41: 14 | F41: 11.9
C42: EV | D42: =D41*$H$37 -> 50323.716 | E42: =E41*$H$37 -> 64048.366 | F42: =F41*$H$37 -> 54441.111
C43: Per Share | D43: =D42/'Question 4'!$C$77 -> 66.469048 | E43: =E42/'Question 4'!$C$77 -> 84.59697 | F43: =F42/'Question 4'!$C$77 -> 71.907425
A45: Year ended Dec. 31 (in millions, except where noted) | C45: 2007A | D45: 2008E | E45: 2009P | F45: 2010P | G45: 2011P | H45: 2012P
A47: Barrels of beer sold: (000)
A48: U.S. | C48: 104.4 | D48: 106.488 | E48: 108.61776 | F48: 110.79012 | G48: 113.00592 | H48: 115.26604
...

Sheet Question 5
B2: There were many things Anheuser-Busch could have done other than just accept InBev’s offer.
B3: 1.) Engage and negotiate:
B4: Anheuser-Busch can negotiate using internal valuation metrics to determine if the $65.00/share is unreasonable and try to negotiate a higher price. They can also explain the great synergies that can occur with InBev’s immediate introduction into the US market. In addition, they can elaborate on their buy-out conditions, rather than strictly thestand-alone price per share (job retention and board seats).
B5: 2.) Reject the bid and convince the market that they are worth more as a stand-alone:
B6: Anheuser-Busch would have to do similar things to what InBev has envisioned for its use of Anheuser-Busch. This entails cost-cutting and strategically divesting in certain areas that are deemed to be holding back their value. Specifically, they can divest in Grupo Modelo and Tsingtao and use the proceeds for funding other domestic operations. Anheuser-Busch can also buy 100% of Grupo Modelo and/or Tsingtao as as tart to showing investors and the public that Anheuser-Busch wants to expand into international markets without being acquired. It can act as a first step before acquiring or partnering with another big firm.
B7: 3.) Find a “white knight”:
B8: This would involve Anheuser-Busch showing investors it is serious about its growth by being acquired by another major firm in the brewing industry that wants to see Anheuser-Busch’s growth without much change. For example, Diageo in London would be great with access to many synergies and 10% of the global beer market.
B9: 4.) “Pac-Man” defense:
B10: This strategy has Anheuser-Busch buying InBev instead, which would not be a bad strategy, giving an immediate introduction to the international markets. The main difficulty is that Anheuser-Busch would have to raise the capital for this acquisition, which can come from the shares, debt, or sponsored partner(s).
B11: 5.) Buy someone else first:
B12: This strategy requires Anheuser-Busch to acquire another brewing company; therefore, making it a lot more difficult for InBev to continue its pursuit of Anheuser-Busch’s acquisition. It would make InBev require a lot more capital, and investors and board members would vote against that acquisition, as there is trouble with antitrust in England’s legislature.

Sheet Question 6
B2: 6. We valued Anheuser-Busch on a stand-alone basis as of December 31, 2007 (t = 0). All forecast cash flows from 2008 onward are discounted back to 12/31/2007.
B4: We used an enterprise DCF based on Free Cash Flow to the Firm (FCFF):
B5: FCFF = NOPAT+D&A−Capex−ΔNWC
B6: NOPAT = EBIT(1−Tax Rate)+Equity income (net of tax)
B8: Why: FCFF values the business independent of capital structure. FCFF is discounted at WACC to get the Enterprise Value (EV), which is then converted into Equity Value by subtracting the Net Debt.
B10: Outcome:
B11: Total PV of FCFF | C11: 13564.67
B12: Terminal Value | C12: 64176.18
B13: PV of TV | C13: 42877.3
B14: Enterprise Value | C14: 56441.98
B15: Equity Value | C15: 47301.68
B16: Price per Share | C16: 65.24
B18: How we arrived at Free Cash Flows:
B19: EBIT
B20: Tax rate
B21: EBIT(1−T)
B22: Equity income (net of tax)
B23: NOPAT
B24: D&A
B25: Capex
B26: ΔNWC
B27: FCFF
